Workbook

Sheet Dashboard MD
A1: HITECH CONSTRUCTION COMPANY LIMITED
A2: ESG & ESAP · SERVICE PROVIDER PAYMENTS DASHBOARD
A4: TOTAL COMMITTED | C4: TOTAL PAID | E4: PIPELINE | G4: UNSCHEDULED | I4: PAYMENT RATE
A5: =SUM('MD Register'!F5:F102) -> 7.5247117e+08 | C5: =SUM('MD Register'!V5:V102) -> 5.0819623e+08 | E5: =SUM('MD Register'!AC5:AC102) -> 31453515 | G5: =A5-C5-E5 -> 2.1282142e+08 | I5: =IF(A5=0,0,C5/A5) -> 0.6753697
A8: Pipeline = upcoming scheduled amounts · Unscheduled = committed - paid - pipeline · Date = paid, No date = pipeline
A10: PAYMENT SUMMARY BY SERVICE PROVIDER
A11: # | B11: Service Provider | C11: Category | D11: Project | E11: Contract (₦) | F11: Paid (₦) | G11: Pipeline (₦) | H11: Unscheduled (₦) | I11: % Paid
A12: =IF(Lists!D2="","",1) -> 1 | B12: =IF(Lists!D2="","",Lists!D2) -> NCF | C12: =IF(B12="","",IFERROR(INDEX('MD Register'!C$5:C$104,MATCH(B12,'MD Register'!B$5:B$104,0)),"")) -> ESAP-BMP | D12: =IF(B12="","",IFERROR(INDEX('MD Register'!D$5:D$104,MATCH(B12,'MD Register'!B$5:B$104,0)),"")) -> LCCH SEC 1&2 | E12: =IF(B12="","",SUMIF('MD Register'!$B$5:$B$104,TRIM(B12),'MD Register'!$F$5:$F$104)) -> 82934896 | F12: =IF(B12="","",SUMIF('MD Register'!$B$5:$B$104,TRIM(B12),'MD Register'!$V$5:$V$104)) -> 62264320 | G12: =IF(B12="","",SUMIF('MD Register'!$B$5:$B$104,TRIM(B12),'MD Register'!$AC$5:$AC$104)) -> 0 | H12: =IF(B12="","",E12-F12-G12) -> 20670576 | I12: =IF(OR(B12="",E12=0),"-",F12/E12) -> 0.75076142
A13: =IF(Lists!D3="","",2) -> 2 | B13: =IF(Lists!D3="","",Lists!D3) -> DynaSmart | C13: =IF(B13="","",IFERROR(INDEX('MD Register'!C$5:C$104,MATCH(B13,'MD Register'!B$5:B$104,0)),"")) -> ESAP-SRAP | D13: =IF(B13="","",IFERROR(INDEX('MD Register'!D$5:D$104,MATCH(B13,'MD Register'!B$5:B$104,0)),"")) -> LCCH SEC 1 | E13: =IF(B13="","",SUMIF('MD Register'!$B$5:$B$104,TRIM(B13),'MD Register'!$F$5:$F$104)) -> 4.5419667e+08 | F13: =IF(B13="","",SUMIF('MD Register'!$B$5:$B$104,TRIM(B13),'MD Register'!$V$5:$V$104)) -> 2.950982e+08 | G13: =IF(B13="","",SUMIF('MD Register'!$B$5:$B$104,TRIM(B13),'MD Register'!$AC$5:$AC$104)) -> 0 | H13: =IF(B13="","",E13-F13-G13) -> 1.5909847e+08 | I13: =IF(OR(B13="",E13=0),"-",F13/E13) -> 0.64971458
A14: =IF(Lists!D4="","",3) -> 3 | B14: =IF(Lists!D4="","",Lists!D4) -> CEO Advisory | C14: =IF(B14="","",IFERROR(INDEX('MD Register'!C$5:C$104,MATCH(B14,'MD Register'!B$5:B$104,0)),"")) -> HRRA | D14: =IF(B14="","",IFERROR(INDEX('MD Register'!D$5:D$104,MATCH(B14,'MD Register'!B$5:B$104,0)),"")) -> LCCH SEC 1 | E14: =IF(B14="","",SUMIF('MD Register'!$B$5:$B$104,TRIM(B14),'MD Register'!$F$5:$F$104)) -> 10050000 | F14: =IF(B14="","",SUMIF('MD Register'!$B$5:$B$104,TRIM(B14),'MD Register'!$V$5:$V$104)) -> 6030000 | G14: =IF(B14="","",SUMIF('MD Register'!$B$5:$B$104,TRIM(B14),'MD Register'!$AC$5:$AC$104)) -> 0 | H14: =IF(B14="","",E14-F14-G14) -> 4020000 | I14: =IF(OR(B14="",E14=0),"-",F14/E14) -> 0.6
A15: =IF(Lists!D5="","",4) -> 4 | B15: =IF(Lists!D5="","",Lists!D5) -> Eddie Perez Limited | C15: =IF(B15="","",IFERROR(INDEX('MD Register'!C$5:C$104,MATCH(B15,'MD Register'!B$5:B$104,0)),"")) -> OD SURVEY | D15: =IF(B15="","",IFERROR(INDEX('MD Register'!D$5:D$104,MATCH(B15,'MD Register'!B$5:B$104,0)),"")) -> LCCH SEC 1 | E15: =IF(B15="","",SUMIF('MD Register'!$B$5:$B$104,TRIM(B15),'MD Register'!$F$5:$F$104)) -> 130664100 | F15: =IF(B15="","",SUMIF('MD Register'!$B$5:$B$104,TRIM(B15),'MD Register'!$V$5:$V$104)) -> 109481532 | G15: =IF(B15="","",SUMIF('MD Register'!$B$5:$B$104,TRIM(B15),'MD Register'!$AC$5:$AC$104)) -> 0 | H15: =IF(B15="","",E15-F15-G15) -> 21182568 | I15: =IF(OR(B15="",E15=0),"-",F15/E15) -> 0.83788533
A16: =IF(Lists!D6="","",5) -> 5 | B16: =IF(Lists!D6="","",Lists!D6) -> David Omaghomi | C16: =IF(B16="","",IFERROR(INDEX('MD Register'!C$5:C$104,MATCH(B16,'MD Register'!B$5:B$104,0)),"")) -> CRM | D16: =IF(B16="","",IFERROR(INDEX('MD Register'!D$5:D$104,MATCH(B16,'MD Register'!B$5:B$104,0)),"")) -> LCCH SEC 1&2 | E16: =IF(B16="","",SUMIF('MD Register'!$B$5:$B$104,TRIM(B16),'MD Register'!$F$5:$F$104)) -> 29964000 | F16: =IF(B16="","",SUMIF('MD Register'!$B$5:$B$104,TRIM(B16),'MD Register'!$V$5:$V$104)) -> 19964000 | G16: =IF(B16="","",SUMIF('MD Register'!$B$5:$B$104,TRIM(B16),'MD Register'!$AC$5:$AC$104)) -> 10000000 | H16: =IF(B16="","",E16-F16-G16) -> 0 | I16: =IF(OR(B16="",E16=0),"-",F16/E16) -> 0.66626619
A17: =IF(Lists!D7="","",6) -> 6 | B17: =IF(Lists!D7="","",Lists!D7) -> Ndoni Logistic | C17: =IF(B17="","",IFERROR(INDEX('MD Register'!C$5:C$104,MATCH(B17,'MD Register'!B$5:B$104,0)),"")) -> CRM | D17: =IF(B17="","",IFERROR(INDEX('MD Register'!D$5:D$104,MATCH(B17,'MD Register'!B$5:B$104,0)),"")) -> LCCH SEC 1&2 | E17: =IF(B17="","",SUMIF('MD Register'!$B$5:$B$104,TRIM(B17),'MD Register'!$F$5:$F$104)) -> 3100000 | F17: =IF(B17="","",SUMIF('MD Register'!$B$5:$B$104,TRIM(B17),'MD Register'!$V$5:$V$104)) -> 3100000 | G17: =IF(B17="","",SUMIF('MD Register'!$B$5:$B$104,TRIM(B17),'MD Register'!$AC$5:$AC$104)) -> 0 | H17: =IF(B17="","",E17-F17-G17) -> 0 | I17: =IF(OR(B17="",E17=0),"-",F17/E17) -> 1
A18: =IF(Lists!D8="","",7) -> 7 | B18: =IF(Lists!D8="","",Lists!D8) -> Hitech-CRM | C18: =IF(B18="","",IFERROR(INDEX('MD Register'!C$5:C$104,MATCH(B18,'MD Register'!B$5:B$104,0)),"")) -> ESAP SEC 1 | D18: =IF(B18="","",IFERROR(INDEX('MD Register'!D$5:D$104,MATCH(B18,'MD Register'!B$5:B$104,0)),"")) -> LCCH SEC 1 | E18: =IF(B18="","",SUMIF('MD Register'!$B$5:$B$104,TRIM(B18),'MD Register'!$F$5:$F$104)) -> 3964400 | F18: =IF(B18="","",SUMIF('MD Register'!$B$5:$B$104,TRIM(B18),'MD Register'!$V$5:$V$104)) -> 3964400 | G18: =IF(B18="","",SUMIF('MD Register'!$B$5:$B$104,TRIM(B18),'MD Register'!$AC$5:$AC$104)) -> 0 | H18: =IF(B18="","",E18-F18-G18) -> 0 | I18: =IF(OR(B18="",E18=0),"-",F18/E18) -> 1
A19: =IF(Lists!D9="","",8) -> 8 | B19: =IF(Lists!D9="","",Lists!D9) -> Beachtv Media Limited | C19: =IF(B19="","",IFERROR(INDEX('MD Register'!C$5:C$104,MATCH(B19,'MD Register'!B$5:B$104,0)),"")) -> CSR | D19: =IF(B19="","",IFERROR(INDEX('MD Register'!D$5:D$104,MATCH(B19,'MD Register'!B$5:B$104,0)),"")) -> LCCH SEC 1 | E19: =IF(B19="","",SUMIF('MD Register'!$B$5:$B$104,TRIM(B19),'MD Register'!$F$5:$F$104)) -> 370000 | F19: =IF(B19="","",SUMIF('MD Register'!$B$5:$B$104,TRIM(B19),'MD Register'!$V$5:$V$104)) -> 120000 | G19: =IF(B19="","",SUMIF('MD Register'!$B$5:$B$104,TRIM(B19),'MD Register'!$AC$5:$AC$104)) -> 250000 | H19: =IF(B19="","",E19-F19-G19) -> 0 | I19: =IF(OR(B19="",E19=0),"-",F19/E19) -> 0.32432432
A20: =IF(Lists!D10="","",9) -> 9 | B20: =IF(Lists!D10="","",Lists!D10) -> G&B PRINTING PRESS AND BUSINESS CENTER | C20: =IF(B20="","",IFERROR(INDEX('MD Register'!C$5:C$104,MATCH(B20,'MD Register'!B$5:B$104,0)),"")) -> CRM | D20: =IF(B20="","",IFERROR(INDEX('MD Register'!D$5:D$104,MATCH(B20,'MD Register'!B$5:B$104,0)),"")) -> LCCH SEC 1&2 | E20: =IF(B20="","",SUMIF('MD Register'!$B$5:$B$104,TRIM(B20),'MD Register'!$F$5:$F$104)) -> 1514500 | F20: =IF(B20="","",SUMIF('MD Register'!$B$5:$B$104,TRIM(B20),'MD Register'!$V$5:$V$104)) -> 0 | G20: =IF(B20="","",SUMIF('MD Register'!$B$5:$B$104,TRIM(B20),'MD Register'!$AC$5:$AC$104)) -> 1514500 | H20: =IF(B20="","",E20-F20-G20) -> 0 | I20: =IF(OR(B20="",E20=0),"-",F20/E20) -> 0
A21: =IF(Lists!D11="","",10) -> 10 | B21: =IF(Lists!D11="","",Lists!D11) -> Lifeline Option Enterprises | C21: =IF(B21="","",IFERROR(INDEX('MD Register'!C$5:C$104,MATCH(B21,'MD Register'!B$5:B$104,0)),"")) -> CSR | D21: =IF(B21="","",IFERROR(INDEX('MD Register'!D$5:D$104,MATCH(B21,'MD Register'!B$5:B$104,0)),"")) -> LCCH SEC 1&2 | E21: =IF(B21="","",SUMIF('MD Register'!$B$5:$B$104,TRIM(B21),'MD Register'!$F$5:$F$104)) -> 1000000 | F21: =IF(B21="","",SUMIF('MD Register'!$B$5:$B$104,TRIM(B21),'MD Register'!$V$5:$V$104)) -> 790000 | G21: =IF(B21="","",SUMIF('MD Register'!$B$5:$B$104,TRIM(B21),'MD Register'!$AC$5:$AC$104)) -> 210000 | H21: =IF(B21="","",E21-F21-G21) -> 0 | I21: =IF(OR(B21="",E21=0),"-",F21/E21) -> 0.79
A22: =IF(Lists!D12="","",11) -> 11 | B22: =IF(Lists!D12="","",Lists!D12) -> CRM Office and SRAP Team | C22: =IF(B22="","",IFERROR(INDEX('MD Register'!C$5:C$104,MATCH(B22,'MD Register'!B$5:B$104,0)),"")) -> ESAP SEC 1 | D22: =IF(B22="","",IFERROR(INDEX('MD Register'!D$5:D$104,MATCH(B22,'MD Register'!B$5:B$104,0)),"")) -> LCCH SEC 1 | E22: =IF(B22="","",SUMIF('MD Register'!$B$5:$B$104,TRIM(B22),'MD Register'!$F$5:$F$104)) -> 872000 | F22: =IF(B22="","",SUMIF('MD Register'!$B$5:$B$104,TRIM(B22),'MD Register'!$V$5:$V$104)) -> 0 | G22: =IF(B22="","",SUMIF('MD Register'!$B$5:$B$104,TRIM(B22),'MD Register'!$AC$5:$AC$104)) -> 872000 | H22: =IF(B22="","",E22-F22-G22) -> 0 | I22: =IF(OR(B22="",E22=0),"-",F22/E22) -> 0
A23: =IF(Lists!D13="","",12) -> 12 | B23: =IF(Lists!D13="","",Lists!D13) -> EcoConserv | C23: =IF(B23="","",IFERROR(INDEX('MD Register'!C$5:C$104,MATCH(B23,'MD Register'!B$5:B$104,0)),"")) -> ESAP SEC 1 | D23: =IF(B23="","",IFERROR(INDEX('MD Register'!D$5:D$104,MATCH(B23,'MD Register'!B$5:B$104,0)),"")) -> LCCH SEC 1 | E23: =IF(B23="","",SUMIF('MD Register'!$B$5:$B$104,TRIM(B23),'MD Register'!$F$5:$F$104)) -> 24612600 | F23: =IF(B23="","",SUMIF('MD Register'!$B$5:$B$104,TRIM(B23),'MD Register'!$V$5:$V$104)) -> 7383780 | G23: =IF(B23="","",SUMIF('MD Register'!$B$5:$B$104,TRIM(B23),'MD Register'!$AC$5:$AC$104)) -> 9379015 | H23: =IF(B23="","",E23-F23-G23) -> 7849805 | I23: =IF(OR(B23="",E23=0),"-",F23/E23) -> 0.3
A24: =IF(Lists!D14="","",13) -> 13 | B24: =IF(Lists!D14="","",Lists!D14) -> Hitech CRM | C24: =IF(B24="","",IFERROR(INDEX('MD Register'!C$5:C$104,MATCH(B24,'MD Register'!B$5:B$104,0)),"")) | D24: =IF(B24="","",IFERROR(INDEX('MD Register'!D$5:D$104,MATCH(B24,'MD Register'!B$5:B$104,0)),"")) | E24: =IF(B24="","",SUMIF('MD Register'!$B$5:$B$104,TRIM(B24),'MD Register'!$F$5:$F$104)) -> 0 | F24: =IF(B24="","",SUMIF('MD Register'!$B$5:$B$104,TRIM(B24),'MD Register'!$V$5:$V$104)) -> 0 | G24: =IF(B24="","",SUMIF('MD Register'!$B$5:$B$104,TRIM(B24),'MD Register'!$AC$5:$AC$104)) -> 0 | H24: =IF(B24="","",E24-F24-G24) -> 0 | I24: =IF(OR(B24="",E24=0),"-",F24/E24) -> -
A25: =IF(Lists!D15="","",14) -> 14 | B25: =IF(Lists!D15="","",Lists!D15) -> Asili | C25: =IF(B25="","",IFERROR(INDEX('MD Register'!C$5:C$104,MATCH(B25,'MD Register'!B$5:B$104,0)),"")) | D25: =IF(B25="","",IFERROR(INDEX('MD Register'!D$5:D$104,MATCH(B25,'MD Register'!B$5:B$104,0)),"")) | E25: =IF(B25="","",SUMIF('MD Register'!$B$5:$B$104,TRIM(B25),'MD Register'!$F$5:$F$104)) -> 0 | F25: =IF(B25="","",SUMIF('MD Register'!$B$5:$B$104,TRIM(B25),'MD Register'!$V$5:$V$104)) -> 0 | G25: =IF(B25="","",SUMIF('MD Register'!$B$5:$B$104,TRIM(B25),'MD Register'!$AC$5:$AC$104)) -> 0 | H25: =IF(B25="","",E25-F25-G25) -> 0 | I25: =IF(OR(B25="",E25=0),"-",F25/E25) -> -
A26: =IF(Lists!D16="","",15) -> 15 | B26: =IF(Lists!D16="","",Lists!D16) -> Other | C26: =IF(B26="","",IFERROR(INDEX('MD Register'!C$5:C$104,MATCH(B26,'MD Register'!B$5:B$104,0)),"")) | D26: =IF(B26="","",IFERROR(INDEX('MD Register'!D$5:D$104,MATCH(B26,'MD Register'!B$5:B$104,0)),"")) | E26: =IF(B26="","",SUMIF('MD Register'!$B$5:$B$104,TRIM(B26),'MD Register'!$F$5:$F$104)) -> 0 | F26: =IF(B26="","",SUMIF('MD Register'!$B$5:$B$104,TRIM(B26),'MD Register'!$V$5:$V$104)) -> 0 | G26: =IF(B26="","",SUMIF('MD Register'!$B$5:$B$104,TRIM(B26),'MD Register'!$AC$5:$AC$104)) -> 0 | H26: =IF(B26="","",E26-F26-G26) -> 0 | I26: =IF(OR(B26="",E26=0),"-",F26/E26) -> -
A27: =IF(Lists!D17="","",16) | B27: =IF(Lists!D17="","",Lists!D17) | C27: =IF(B27="","",IFERROR(INDEX('MD Register'!C$5:C$104,MATCH(B27,'MD Register'!B$5:B$104,0)),"")) | D27: =IF(B27="","",IFERROR(INDEX('MD Register'!D$5:D$104,MATCH(B27,'MD Register'!B$5:B$104,0)),"")) | E27: =IF(B27="","",SUMIF('MD Register'!$B$5:$B$104,TRIM(B27),'MD Register'!$F$5:$F$104)) | F27: =IF(B27="","",SUMIF('MD Register'!$B$5:$B$104,TRIM(B27),'MD Register'!$V$5:$V$104)) | G27: =IF(B27="","",SUMIF('MD Register'!$B$5:$B$104,TRIM(B27),'MD Register'!$AC$5:$AC$104)) | H27: =IF(B27="","",E27-F27-G27) | I27: =IF(OR(B27="",E27=0),"-",F27/E27) -> -
A28: =IF(Lists!D18="","",17) | B28: =IF(Lists!D18="","",Lists!D18) | C28: =IF(B28="","",IFERROR(INDEX('MD Register'!C$5:C$104,MATCH(B28,'MD Register'!B$5:B$104,0)),"")) | D28: =IF(B28="","",IFERROR(INDEX('MD Register'!D$5:D$104,MATCH(B28,'MD Register'!B$5:B$104,0)),"")) | E28: =IF(B28="","",SUMIF('MD Register'!$B$5:$B$104,TRIM(B28),'MD Register'!$F$5:$F$104)) | F28: =IF(B28="","",SUMIF('MD Register'!$B$5:$B$104,TRIM(B28),'MD Register'!$V$5:$V$104)) | G28: =IF(B28="","",SUMIF('MD Register'!$B$5:$B$104,TRIM(B28),'MD Register'!$AC$5:$AC$104)) | H28: =IF(B28="","",E28-F28-G28) | I28: =IF(OR(B28="",E28=0),"-",F28/E28) -> -
A29: =IF(Lists!D19="","",18) | B29: =IF(Lists!D19="","",Lists!D19) | C29: =IF(B29="","",IFERROR(INDEX('MD Register'!C$5:C$104,MATCH(B29,'MD Register'!B$5:B$104,0)),"")) | D29: =IF(B29="","",IFERROR(INDEX('MD Register'!D$5:D$104,MATCH(B29,'MD Register'!B$5:B$104,0)),"")) | E29: =IF(B29="","",SUMIF('MD Register'!$B$5:$B$104,TRIM(B29),'MD Register'!$F$5:$F$104)) | F29: =IF(B29="","",SUMIF('MD Register'!$B$5:$B$104,TRIM(B29),'MD Register'!$V$5:$V$104)) | G29: =IF(B29="","",SUMIF('MD Register'!$B$5:$B$104,TRIM(B29),'MD Register'!$AC$5:$AC$104)) | H29: =IF(B29="","",E29-F29-G29) | I29: =IF(OR(B29="",E29=0),"-",F29/E29) -> -
A30: =IF(Lists!D20="","",19) | B30: =IF(Lists!D20="","",Lists!D20) | C30: =IF(B30="","",IFERROR(INDEX('MD Register'!C$5:C$104,MATCH(B30,'MD Register'!B$5:B$104,0)),"")) | D30: =IF(B30="","",IFERROR(INDEX('MD Register'!D$5:D$104,MATCH(B30,'MD Register'!B$5:B$104,0)),"")) | E30: =IF(B30="","",SUMIF('MD Register'!$B$5:$B$104,TRIM(B30),'MD Register'!$F$5:$F$104)) | F30: =IF(B30="","",SUMIF('MD Register'!$B$5:$B$104,TRIM(B30),'MD Register'!$V$5:$V$104)) | G30: =IF(B30="","",SUMIF('MD Register'!$B$5:$B$104,TRIM(B30),'MD Register'!$AC$5:$AC$104)) | H30: =IF(B30="","",E30-F30-G30) | I30: =IF(OR(B30="",E30=0),"-",F30/E30) -> -
A31: =IF(Lists!D21="","",20) | B31: =IF(Lists!D21="","",Lists!D21) | C31: =IF(B31="","",IFERROR(INDEX('MD Register'!C$5:C$104,MATCH(B31,'MD Register'!B$5:B$104,0)),"")) | D31: =IF(B31="","",IFERROR(INDEX('MD Register'!D$5:D$104,MATCH(B31,'MD Register'!B$5:B$104,0)),"")) | E31: =IF(B31="","",SUMIF('MD Register'!$B$5:$B$104,TRIM(B31),'MD Register'!$F$5:$F$104)) | F31: =IF(B31="","",SUMIF('MD Register'!$B$5:$B$104,TRIM(B31),'MD Register'!$V$5:$V$104)) | G31: =IF(B31="","",SUMIF('MD Register'!$B$5:$B$104,TRIM(B31),'MD Register'!$AC$5:$AC$104)) | H31: =IF(B31="","",E31-F31-G31) | I31: =IF(OR(B31="",E31=0),"-",F31/E31) -> -
A32: =IF(Lists!D22="","",21) | B32: =IF(Lists!D22="","",Lists!D22) | C32: =IF(B32="","",IFERROR(INDEX('MD Register'!C$5:C$104,MATCH(B32,'MD Register'!B$5:B$104,0)),"")) | D32: =IF(B32="","",IFERROR(INDEX('MD Register'!D$5:D$104,MATCH(B32,'MD Register'!B$5:B$104,0)),"")) | E32: =IF(B32="","",SUMIF('MD Register'!$B$5:$B$104,TRIM(B32),'MD Register'!$F$5:$F$104)) | F32: =IF(B32="","",SUMIF('MD Register'!$B$5:$B$104,TRIM(B32),'MD Register'!$V$5:$V$104)) | G32: =IF(B32="","",SUMIF('MD Register'!$B$5:$B$104,TRIM(B32),'MD Register'!$AC$5:$AC$104)) | H32: =IF(B32="","",E32-F32-G32) | I32: =IF(OR(B32="",E32=0),"-",F32/E32) -> -
A33: =IF(Lists!D23="","",22) | B33: =IF(Lists!D23="","",Lists!D23) | C33: =IF(B33="","",IFERROR(INDEX('MD Register'!C$5:C$104,MATCH(B33,'MD Register'!B$5:B$104,0)),"")) | D33: =IF(B33="","",IFERROR(INDEX('MD Register'!D$5:D$104,MATCH(B33,'MD Register'!B$5:B$104,0)),"")) | E33: =IF(B33="","",SUMIF('MD Register'!$B$5:$B$104,TRIM(B33),'MD Register'!$F$5:$F$104)) | F33: =IF(B33="","",SUMIF('MD Register'!$B$5:$B$104,TRIM(B33),'MD Register'!$V$5:$V$104)) | G33: =IF(B33="","",SUMIF('MD Register'!$B$5:$B$104,TRIM(B33),'MD Register'!$AC$5:$AC$104)) | H33: =IF(B33="","",E33-F33-G33) | I33: =IF(OR(B33="",E33=0),"-",F33/E33) -> -
A34: =IF(Lists!D24="","",23) | B34: =IF(Lists!D24="","",Lists!D24) | C34: =IF(B34="","",IFERROR(INDEX('MD Register'!C$5:C$104,MATCH(B34,'MD Register'!B$5:B$104,0)),"")) | D34: =IF(B34="","",IFERROR(INDEX('MD Register'!D$5:D$104,MATCH(B34,'MD Register'!B$5:B$104,0)),"")) | E34: =IF(B34="","",SUMIF('MD Register'!$B$5:$B$104,TRIM(B34),'MD Register'!$F$5:$F$104)) | F34: =IF(B34="","",SUMIF('MD Register'!$B$5:$B$104,TRIM(B34),'MD Register'!$V$5:$V$104)) | G34: =IF(B34="","",SUMIF('MD Register'!$B$5:$B$104,TRIM(B34),'MD Register'!$AC$5:$AC$104)) | H34: =IF(B34="","",E34-F34-G34) | I34: =IF(OR(B34="",E34=0),"-",F34/E34) -> -
A35: =IF(Lists!D25="","",24) | B35: =IF(Lists!D25="","",Lists!D25) | C35: =IF(B35="","",IFERROR(INDEX('MD Register'!C$5:C$104,MATCH(B35,'MD Register'!B$5:B$104,0)),"")) | D35: =IF(B35="","",IFERROR(INDEX('MD Register'!D$5:D$104,MATCH(B35,'MD Register'!B$5:B$104,0)),"")) | E35: =IF(B35="","",SUMIF('MD Register'!$B$5:$B$104,TRIM(B35),'MD Register'!$F$5:$F$104)) | F35: =IF(B35="","",SUMIF('MD Register'!$B$5:$B$104,TRIM(B35),'MD Register'!$V$5:$V$104)) | G35: =IF(B35="","",SUMIF('MD Register'!$B$5:$B$104,TRIM(B35),'MD Register'!$AC$5:$AC$104)) | H35: =IF(B35="","",E35-F35-G35) | I35: =IF(OR(B35="",E35=0),"-",F35/E35) -> -
A36: =IF(Lists!D26="","",25) | B36: =IF(Lists!D26="","",Lists!D26) | C36: =IF(B36="","",IFERROR(INDEX('MD Register'!C$5:C$104,MATCH(B36,'MD Register'!B$5:B$104,0)),"")) | D36: =IF(B36="","",IFERROR(INDEX('MD Register'!D$5:D$104,MATCH(B36,'MD Register'!B$5:B$104,0)),"")) | E36: =IF(B36="","",SUMIF('MD Register'!$B$5:$B$104,TRIM(B36),'MD Register'!$F$5:$F$104)) | F36: =IF(B36="","",SUMIF('MD Register'!$B$5:$B$104,TRIM(B36),'MD Register'!$V$5:$V$104)) | G36: =IF(B36="","",SUMIF('MD Register'!$B$5:$B$104,TRIM(B36),'MD Register'!$AC$5:$AC$104)) | H36: =IF(B36="","",E36-F36-G36) | I36: =IF(OR(B36="",E36=0),"-",F36/E36) -> -
A37: =IF(Lists!D27="","",26) | B37: =IF(Lists!D27="","",Lists!D27) | C37: =IF(B37="","",IFERROR(INDEX('MD Register'!C$5:C$104,MATCH(B37,'MD Register'!B$5:B$104,0)),"")) | D37: =IF(B37="","",IFERROR(INDEX('MD Register'!D$5:D$104,MATCH(B37,'MD Register'!B$5:B$104,0)),"")) | E37: =IF(B37="","",SUMIF('MD Register'!$B$5:$B$104,TRIM(B37),'MD Register'!$F$5:$F$104)) | F37: =IF(B37="","",SUMIF('MD Register'!$B$5:$B$104,TRIM(B37),'MD Register'!$V$5:$V$104)) | G37: =IF(B37="","",SUMIF('MD Register'!$B$5:$B$104,TRIM(B37),'MD Register'!$AC$5:$AC$104)) | H37: =IF(B37="","",E37-F37-G37) | I37: =IF(OR(B37="",E37=0),"-",F37/E37) -> -
A38: =IF(Lists!D28="","",27) | B38: =IF(Lists!D28="","",Lists!D28) | C38: =IF(B38="","",IFERROR(INDEX('MD Register'!C$5:C$104,MATCH(B38,'MD Register'!B$5:B$104,0)),"")) | D38: =IF(B38="","",IFERROR(INDEX('MD Register'!D$5:D$104,MATCH(B38,'MD Register'!B$5:B$104,0)),"")) | E38: =IF(B38="","",SUMIF('MD Register'!$B$5:$B$104,TRIM(B38),'MD Register'!$F$5:$F$104)) | F38: =IF(B38="","",SUMIF('MD Register'!$B$5:$B$104,TRIM(B38),'MD Register'!$V$5:$V$104)) | G38: =IF(B38="","",SUMIF('MD Register'!$B$5:$B$104,TRIM(B38),'MD Register'!$AC$5:$AC$104)) | H38: =IF(B38="","",E38-F38-G38) | I38: =IF(OR(B38="",E38=0),"-",F38/E38) -> -
A39: =IF(Lists!D29="","",28) | B39: =IF(Lists!D29="","",Lists!D29) | C39: =IF(B39="","",IFERROR(INDEX('MD Register'!C$5:C$104,MATCH(B39,'MD Register'!B$5:B$104,0)),"")) | D39: =IF(B39="","",IFERROR(INDEX('MD Register'!D$5:D$104,MATCH(B39,'MD Register'!B$5:B$104,0)),"")) | E39: =IF(B39="","",SUMIF('MD Register'!$B$5:$B$104,TRIM(B39),'MD Register'!$F$5:$F$104)) | F39: =IF(B39="","",SUMIF('MD Register'!$B$5:$B$104,TRIM(B39),'MD Register'!$V$5:$V$104)) | G39: =IF(B39="","",SUMIF('MD Register'!$B$5:$B$104,TRIM(B39),'MD Register'!$AC$5:$AC$104)) | H39: =IF(B39="","",E39-F39-G39) | I39: =IF(OR(B39="",E39=0),"-",F39/E39) -> -
A40: =IF(Lists!D30="","",29) | B40: =IF(Lists!D30="","",Lists!D30) | C40: =IF(B40="","",IFERROR(INDEX('MD Register'!C$5:C$104,MATCH(B40,'MD Register'!B$5:B$104,0)),"")) | D40: =IF(B40="","",IFERROR(INDEX('MD Register'!D$5:D$104,MATCH(B40,'MD Register'!B$5:B$104,0)),"")) | E40: =IF(B40="","",SUMIF('MD Register'!$B$5:$B$104,TRIM(B40),'MD Register'!$F$5:$F$104)) | F40: =IF(B40="","",SUMIF('MD Register'!$B$5:$B$104,TRIM(B40),'MD Register'!$V$5:$V$104)) | G40: =IF(B40="","",SUMIF('MD Register'!$B$5:$B$104,TRIM(B40),'MD Register'!$AC$5:$AC$104)) | H40: =IF(B40="","",E40-F40-G40) | I40: =IF(OR(B40="",E40=0),"-",F40/E40) -> -
A41: =IF(Lists!D31="","",30) | B41: =IF(Lists!D31="","",Lists!D31) | C41: =IF(B41="","",IFERROR(INDEX('MD Register'!C$5:C$104,MATCH(B41,'MD Register'!B$5:B$104,0)),"")) | D41: =IF(B41="","",IFERROR(INDEX('MD Register'!D$5:D$104,MATCH(B41,'MD Register'!B$5:B$104,0)),"")) | E41: =IF(B41="","",SUMIF('MD Register'!$B$5:$B$104,TRIM(B41),'MD Register'!$F$5:$F$104)) | F41: =IF(B41="","",SUMIF('MD Register'!$B$5:$B$104,TRIM(B41),'MD Register'!$V$5:$V$104)) | G41: =IF(B41="","",SUMIF('MD Register'!$B$5:$B$104,TRIM(B41),'MD Register'!$AC$5:$AC$104)) | H41: =IF(B41="","",E41-F41-G41) | I41: =IF(OR(B41="",E41=0),"-",F41/E41) -> -
A42: TOTAL | E42: =SUM(E12:E41) -> 7.4324317e+08 | F42: =SUM(F12:F41) -> 5.0819623e+08 | G42: =SUM(G12:G41) -> 22225515 | H42: =SUM(H12:H41) -> 2.1282142e+08 | I42: =IF(E42=0,0,F42/E42) -> 0.683755
A44: PROJECT COVERAGE
A45: # | B45: Project | C45: # Lines | D45: Contract (₦) | E45: Paid (₦) | F45: Pipeline (₦) | G45: % Paid
...

Sheet MD Register
A1: PAYMENT REGISTER — ESAP & ESG SERVICE PROVIDERS
A2: Yellow cells = to be completed | White cells = auto-calculated | DATE = tranche paid (even approximate) | No date = pipeline/upcoming | All amounts in ₦
A3: # | B3: Service Provider | C3: Category | D3: Project | E3: Description | F3: Contract Amount (₦) | G3: TRANCHE 1 | J3: TRANCHE 2 | M3: TRANCHE 3 | P3: TRANCHE 4 | S3: ONE-SHOT | V3: Total Paid (₦) | W3: Balance (₦) | X3: % Paid | Y3: Status | Z3: Invoice # | AA3: Contract # | AB3: Notes | AC3: Pipeline (₦)
G4: Amount (₦) | H4: Date | I4: Ref/POP | J4: Amount (₦) | K4: Date | L4: Ref/POP | M4: Amount (₦) | N4: Date | O4: Ref/POP | P4: Amount (₦) | Q4: Date | R4: Ref/POP | S4: Amount (₦) | T4: Date | U4: Ref/POP | Z4: Ref | AA4: Ref | AB4: Details | AC4: À VENIR
A5: =IF(B5="","",ROW()-4) -> 1 | B5: NCF | C5: ESAP-BMP | D5: LCCH SEC 1&2 | E5: BMP Implementation Phase 1+ 2 | F5: 82934896 | G5: 14546700 | H5: =DATE(2025,10,20) -> 45950 | I5: POP Access Bank | J5: 47717620 | K5: 46063 | V5: =IF(TRIM(Y5)="PAID",SUM(G5,J5,M5,P5,S5),IF(AND(H5<>"",LEN(TRIM(H5))>0),G5,0)+IF(AND(K5<>"",LEN(TRIM(K5))>0),J5,0)+IF(AND(N5<>"",LEN(TRIM(N5))>0),M5,0)+IF(AND(Q5<>"",LEN(TRIM(Q5))>0),P5,0)+IF(AND(T5<>"",LEN(TRIM(T5))>0),S5,0)) -> 62264320 | W5: =IF(OR(F5="",F5=0),"",MAX(0,F5-V5-AC5)) -> 20670576 | X5: =IF(OR(F5=0,F5=""),"-",V5/F5) -> 0.75076142 | Y5: PARTIAL | Z5: 0120054 / 0120065 | AB5: POP Access Bank | AC5: =IF(TRIM(Y5)="PAID",0,IF((IF(AND(OR(H5="",LEN(TRIM(H5))=0),ISNUMBER(G5),G5>0),G5,0)+IF(AND(OR(K5="",LEN(TRIM(K5))=0),ISNUMBER(J5),J5>0),J5,0)+IF(AND(OR(N5="",LEN(TRIM(N5))=0),ISNUMBER(M5),M5>0),M5,0)+IF(AND(OR(Q5="",LEN(TRIM(Q5))=0),ISNUMBER(P5),P5>0),P5,0)+IF(AND(OR(T5="",LEN(TRIM(T5))=0),ISNUMBER(S5),S5>0),S5,0))>0,IF(AND(OR(H5="",LEN(TRIM(H5))=0),ISNUMBER(G5),G5>0),G5,0)+IF(AND(OR(K5="",LEN(TRIM(K5))=0),ISNUMBER(J5),J5>0),J5,0)+IF(AND(OR(N5="",LEN(TRIM(N5))=0),ISNUMBER(M5),M5>0),M5,0)+IF(AND(OR(Q5="",LEN(TRIM(Q5))=0),ISNUMBER(P5),P5>0),P5,0)+IF(AND(OR(T5="",LEN(TRIM(T5))=0),ISNUMBER(S5),S5>0),S5,0),IF(OR(TRIM(Y5)="UPCOMING",TRIM(Y5)="PENDING"),MAX(0,F5-V5),0))) -> 0
A6: =IF(B6="","",ROW()-4) -> 2 | B6: DynaSmart | C6: ESAP-SRAP | D6: LCCH SEC 1 | E6: SRAP - Contract signing (35%) + Inception Report (30%) | F6: 4.5419667e+08 | G6: 158970000 | H6: 45992 | J6: 1.361282e+08 | K6: 46063 | V6: =IF(TRIM(Y6)="PAID",SUM(G6,J6,M6,P6,S6),IF(AND(H6<>"",LEN(TRIM(H6))>0),G6,0)+IF(AND(K6<>"",LEN(TRIM(K6))>0),J6,0)+IF(AND(N6<>"",LEN(TRIM(N6))>0),M6,0)+IF(AND(Q6<>"",LEN(TRIM(Q6))>0),P6,0)+IF(AND(T6<>"",LEN(TRIM(T6))>0),S6,0)) -> 2.950982e+08 | W6: =IF(OR(F6="",F6=0),"",MAX(0,F6-V6-AC6)) -> 1.5909847e+08 | X6: =IF(OR(F6=0,F6=""),"-",V6/F6) -> 0.64971458 | Y6: PARTIAL | Z6: 101 / 102 | AA6: HCCL/HO/CON-CA/25/004 | AB6: USD $110,141.40 - NGN TBC (T1) | AC6: =IF(TRIM(Y6)="PAID",0,IF((IF(AND(OR(H6="",LEN(TRIM(H6))=0),ISNUMBER(G6),G6>0),G6,0)+IF(AND(OR(K6="",LEN(TRIM(K6))=0),ISNUMBER(J6),J6>0),J6,0)+IF(AND(OR(N6="",LEN(TRIM(N6))=0),ISNUMBER(M6),M6>0),M6,0)+IF(AND(OR(Q6="",LEN(TRIM(Q6))=0),ISNUMBER(P6),P6>0),P6,0)+IF(AND(OR(T6="",LEN(TRIM(T6))=0),ISNUMBER(S6),S6>0),S6,0))>0,IF(AND(OR(H6="",LEN(TRIM(H6))=0),ISNUMBER(G6),G6>0),G6,0)+IF(AND(OR(K6="",LEN(TRIM(K6))=0),ISNUMBER(J6),J6>0),J6,0)+IF(AND(OR(N6="",LEN(TRIM(N6))=0),ISNUMBER(M6),M6>0),M6,0)+IF(AND(OR(Q6="",LEN(TRIM(Q6))=0),ISNUMBER(P6),P6>0),P6,0)+IF(AND(OR(T6="",LEN(TRIM(T6))=0),ISNUMBER(S6),S6>0),S6,0),IF(OR(TRIM(Y6)="UPCOMING",TRIM(Y6)="PENDING"),MAX(0,F6-V6),0))) -> 0
A7: =IF(B7="","",ROW()-4) -> 3 | B7: CEO Advisory | C7: HRRA | D7: LCCH SEC 1 | E7: Mobilization (30%) + Draft Report 30% | F7: 10050000 | G7: 3015000 | H7: 45874 | I7: POP FirstBank | J7: 3015000 | K7: 46063 | V7: =IF(TRIM(Y7)="PAID",SUM(G7,J7,M7,P7,S7),IF(AND(H7<>"",LEN(TRIM(H7))>0),G7,0)+IF(AND(K7<>"",LEN(TRIM(K7))>0),J7,0)+IF(AND(N7<>"",LEN(TRIM(N7))>0),M7,0)+IF(AND(Q7<>"",LEN(TRIM(Q7))>0),P7,0)+IF(AND(T7<>"",LEN(TRIM(T7))>0),S7,0)) -> 6030000 | W7: =IF(OR(F7="",F7=0),"",MAX(0,F7-V7-AC7)) -> 4020000 | X7: =IF(OR(F7=0,F7=""),"-",V7/F7) -> 0.6 | Y7: PARTIAL | AB7: POP FirstBank | AC7: =IF(TRIM(Y7)="PAID",0,IF((IF(AND(OR(H7="",LEN(TRIM(H7))=0),ISNUMBER(G7),G7>0),G7,0)+IF(AND(OR(K7="",LEN(TRIM(K7))=0),ISNUMBER(J7),J7>0),J7,0)+IF(AND(OR(N7="",LEN(TRIM(N7))=0),ISNUMBER(M7),M7>0),M7,0)+IF(AND(OR(Q7="",LEN(TRIM(Q7))=0),ISNUMBER(P7),P7>0),P7,0)+IF(AND(OR(T7="",LEN(TRIM(T7))=0),ISNUMBER(S7),S7>0),S7,0))>0,IF(AND(OR(H7="",LEN(TRIM(H7))=0),ISNUMBER(G7),G7>0),G7,0)+IF(AND(OR(K7="",LEN(TRIM(K7))=0),ISNUMBER(J7),J7>0),J7,0)+IF(AND(OR(N7="",LEN(TRIM(N7))=0),ISNUMBER(M7),M7>0),M7,0)+IF(AND(OR(Q7="",LEN(TRIM(Q7))=0),ISNUMBER(P7),P7>0),P7,0)+IF(AND(OR(T7="",LEN(TRIM(T7))=0),ISNUMBER(S7),S7>0),S7,0),IF(OR(TRIM(Y7)="UPCOMING",TRIM(Y7)="PENDING"),MAX(0,F7-V7),0))) -> 0
A8: =IF(B8="","",ROW()-4) -> 4 | B8: Eddie Perez Limited | C8: OD SURVEY | D8: LCCH SEC 1 | E8: Mobilization fee for survey (60%) + Draft Report (30%) | F8: 53793000 | G8: 32275800 | H8: 45988 | J8: 16137900 | K8: 46063 | V8: =IF(TRIM(Y8)="PAID",SUM(G8,J8,M8,P8,S8),IF(AND(H8<>"",LEN(TRIM(H8))>0),G8,0)+IF(AND(K8<>"",LEN(TRIM(K8))>0),J8,0)+IF(AND(N8<>"",LEN(TRIM(N8))>0),M8,0)+IF(AND(Q8<>"",LEN(TRIM(Q8))>0),P8,0)+IF(AND(T8<>"",LEN(TRIM(T8))>0),S8,0)) -> 48413700 | W8: =IF(OR(F8="",F8=0),"",MAX(0,F8-V8-AC8)) -> 5379300 | X8: =IF(OR(F8=0,F8=""),"-",V8/F8) -> 0.9 | Y8: PARTIAL | Z8: INV-210126 | AB8: Next: Final 10% Q1 2026 | AC8: =IF(TRIM(Y8)="PAID",0,IF((IF(AND(OR(H8="",LEN(TRIM(H8))=0),ISNUMBER(G8),G8>0),G8,0)+IF(AND(OR(K8="",LEN(TRIM(K8))=0),ISNUMBER(J8),J8>0),J8,0)+IF(AND(OR(N8="",LEN(TRIM(N8))=0),ISNUMBER(M8),M8>0),M8,0)+IF(AND(OR(Q8="",LEN(TRIM(Q8))=0),ISNUMBER(P8),P8>0),P8,0)+IF(AND(OR(T8="",LEN(TRIM(T8))=0),ISNUMBER(S8),S8>0),S8,0))>0,IF(AND(OR(H8="",LEN(TRIM(H8))=0),ISNUMBER(G8),G8>0),G8,0)+IF(AND(OR(K8="",LEN(TRIM(K8))=0),ISNUMBER(J8),J8>0),J8,0)+IF(AND(OR(N8="",LEN(TRIM(N8))=0),ISNUMBER(M8),M8>0),M8,0)+IF(AND(OR(Q8="",LEN(TRIM(Q8))=0),ISNUMBER(P8),P8>0),P8,0)+IF(AND(OR(T8="",LEN(TRIM(T8))=0),ISNUMBER(S8),S8>0),S8,0),IF(OR(TRIM(Y8)="UPCOMING",TRIM(Y8)="PENDING"),MAX(0,F8-V8),0))) -> 0
A9: =IF(B9="","",ROW()-4) -> 5 | B9: Eddie Perez Limited | C9: SOCIO ECONOMIC SURVEYS | D9: LCCH SEC 1&2 | E9: Mobilization (50%) + Draft report (30%) | F9: 76871100 | G9: 38435550 | H9: =DATE(2026,1,6) -> 46028 | I9: TBC - Emile Antone | J9: 22632282 | K9: 46063 | V9: =IF(TRIM(Y9)="PAID",SUM(G9,J9,M9,P9,S9),IF(AND(H9<>"",LEN(TRIM(H9))>0),G9,0)+IF(AND(K9<>"",LEN(TRIM(K9))>0),J9,0)+IF(AND(N9<>"",LEN(TRIM(N9))>0),M9,0)+IF(AND(Q9<>"",LEN(TRIM(Q9))>0),P9,0)+IF(AND(T9<>"",LEN(TRIM(T9))>0),S9,0)) -> 61067832 | W9: =IF(OR(F9="",F9=0),"",MAX(0,F9-V9-AC9)) -> 15803268 | X9: =IF(OR(F9=0,F9=""),"-",V9/F9) -> 0.7944186 | Y9: PARTIAL | Z9: INV-260925 / INV-161225 | AB9: POP FirstBank | WHT deducted | Next: Final 20% Q1 2026 | AC9: =IF(TRIM(Y9)="PAID",0,IF((IF(AND(OR(H9="",LEN(TRIM(H9))=0),ISNUMBER(G9),G9>0),G9,0)+IF(AND(OR(K9="",LEN(TRIM(K9))=0),ISNUMBER(J9),J9>0),J9,0)+IF(AND(OR(N9="",LEN(TRIM(N9))=0),ISNUMBER(M9),M9>0),M9,0)+IF(AND(OR(Q9="",LEN(TRIM(Q9))=0),ISNUMBER(P9),P9>0),P9,0)+IF(AND(OR(T9="",LEN(TRIM(T9))=0),ISNUMBER(S9),S9>0),S9,0))>0,IF(AND(OR(H9="",LEN(TRIM(H9))=0),ISNUMBER(G9),G9>0),G9,0)+IF(AND(OR(K9="",LEN(TRIM(K9))=0),ISNUMBER(J9),J9>0),J9,0)+IF(AND(OR(N9="",LEN(TRIM(N9))=0),ISNUMBER(M9),M9>0),M9,0)+IF(AND(OR(Q9="",LEN(TRIM(Q9))=0),ISNUMBER(P9),P9>0),P9,0)+IF(AND(OR(T9="",LEN(TRIM(T9))=0),ISNUMBER(S9),S9>0),S9,0),IF(OR(TRIM(Y9)="UPCOMING",TRIM(Y9)="PENDING"),MAX(0,F9-V9),0))) -> 0
A10: =IF(B10="","",ROW()-4) -> 6 | B10: David Omaghomi | C10: CRM | D10: LCCH SEC 1&2 | E10: Communitiy Awareness Campaigns (June - Sept 2025) | F10: 1750000 | S10: 1750000 | T10: 45972 | V10: =IF(TRIM(Y10)="PAID",SUM(G10,J10,M10,P10,S10),IF(AND(H10<>"",LEN(TRIM(H10))>0),G10,0)+IF(AND(K10<>"",LEN(TRIM(K10))>0),J10,0)+IF(AND(N10<>"",LEN(TRIM(N10))>0),M10,0)+IF(AND(Q10<>"",LEN(TRIM(Q10))>0),P10,0)+IF(AND(T10<>"",LEN(TRIM(T10))>0),S10,0)) -> 1750000 | W10: =IF(OR(F10="",F10=0),"",MAX(0,F10-V10-AC10)) -> 0 | X10: =IF(OR(F10=0,F10=""),"-",V10/F10) -> 1 | Y10: PAID | Z10: — | AB10: TBC - Emile Antone | AC10: =IF(TRIM(Y10)="PAID",0,IF((IF(AND(OR(H10="",LEN(TRIM(H10))=0),ISNUMBER(G10),G10>0),G10,0)+IF(AND(OR(K10="",LEN(TRIM(K10))=0),ISNUMBER(J10),J10>0),J10,0)+IF(AND(OR(N10="",LEN(TRIM(N10))=0),ISNUMBER(M10),M10>0),M10,0)+IF(AND(OR(Q10="",LEN(TRIM(Q10))=0),ISNUMBER(P10),P10>0),P10,0)+IF(AND(OR(T10="",LEN(TRIM(T10))=0),ISNUMBER(S10),S10>0),S10,0))>0,IF(AND(OR(H10="",LEN(TRIM(H10))=0),ISNUMBER(G10),G10>0),G10,0)+IF(AND(OR(K10="",LEN(TRIM(K10))=0),ISNUMBER(J10),J10>0),J10,0)+IF(AND(OR(N10="",LEN(TRIM(N10))=0),ISNUMBER(M10),M10>0),M10,0)+IF(AND(OR(Q10="",LEN(TRIM(Q10))=0),ISNUMBER(P10),P10>0),P10,0)+IF(AND(OR(T10="",LEN(TRIM(T10))=0),ISNUMBER(S10),S10>0),S10,0),IF(OR(TRIM(Y10)="UPCOMING",TRIM(Y10)="PENDING"),MAX(0,F10-V10),0))) -> 0
A11: =IF(B11="","",ROW()-4) -> 7 | B11: Hitech-CRM | C11: ESAP SEC 1 | D11: LCCH SEC 1 | E11: GRC Activity | F11: 3964400 | S11: 3964400 | T11: 45965 | V11: =IF(TRIM(Y11)="PAID",SUM(G11,J11,M11,P11,S11),IF(AND(H11<>"",LEN(TRIM(H11))>0),G11,0)+IF(AND(K11<>"",LEN(TRIM(K11))>0),J11,0)+IF(AND(N11<>"",LEN(TRIM(N11))>0),M11,0)+IF(AND(Q11<>"",LEN(TRIM(Q11))>0),P11,0)+IF(AND(T11<>"",LEN(TRIM(T11))>0),S11,0)) -> 3964400 | W11: =IF(OR(F11="",F11=0),"",MAX(0,F11-V11-AC11)) -> 0 | X11: =IF(OR(F11=0,F11=""),"-",V11/F11) -> 1 | Y11: PAID | AC11: =IF(TRIM(Y11)="PAID",0,IF((IF(AND(OR(H11="",LEN(TRIM(H11))=0),ISNUMBER(G11),G11>0),G11,0)+IF(AND(OR(K11="",LEN(TRIM(K11))=0),ISNUMBER(J11),J11>0),J11,0)+IF(AND(OR(N11="",LEN(TRIM(N11))=0),ISNUMBER(M11),M11>0),M11,0)+IF(AND(OR(Q11="",LEN(TRIM(Q11))=0),ISNUMBER(P11),P11>0),P11,0)+IF(AND(OR(T11="",LEN(TRIM(T11))=0),ISNUMBER(S11),S11>0),S11,0))>0,IF(AND(OR(H11="",LEN(TRIM(H11))=0),ISNUMBER(G11),G11>0),G11,0)+IF(AND(OR(K11="",LEN(TRIM(K11))=0),ISNUMBER(J11),J11>0),J11,0)+IF(AND(OR(N11="",LEN(TRIM(N11))=0),ISNUMBER(M11),M11>0),M11,0)+IF(AND(OR(Q11="",LEN(TRIM(Q11))=0),ISNUMBER(P11),P11>0),P11,0)+IF(AND(OR(T11="",LEN(TRIM(T11))=0),ISNUMBER(S11),S11>0),S11,0),IF(OR(TRIM(Y11)="UPCOMING",TRIM(Y11)="PENDING"),MAX(0,F11-V11),0))) -> 0
A12: =IF(B12="","",ROW()-4) -> 8 | B12: Beachtv Media Limited | C12: CSR | D12: LCCH SEC 1 | E12: Photography Videography - Lagos City Marathon | F12: 120000 | S12: 120000 | V12: =IF(TRIM(Y12)="PAID",SUM(G12,J12,M12,P12,S12),IF(AND(H12<>"",LEN(TRIM(H12))>0),G12,0)+IF(AND(K12<>"",LEN(TRIM(K12))>0),J12,0)+IF(AND(N12<>"",LEN(TRIM(N12))>0),M12,0)+IF(AND(Q12<>"",LEN(TRIM(Q12))>0),P12,0)+IF(AND(T12<>"",LEN(TRIM(T12))>0),S12,0)) -> 120000 | W12: =IF(OR(F12="",F12=0),"",MAX(0,F12-V12-AC12)) -> 0 | X12: =IF(OR(F12=0,F12=""),"-",V12/F12) -> 1 | Y12: PAID | AC12: =IF(TRIM(Y12)="PAID",0,IF((IF(AND(OR(H12="",LEN(TRIM(H12))=0),ISNUMBER(G12),G12>0),G12,0)+IF(AND(OR(K12="",LEN(TRIM(K12))=0),ISNUMBER(J12),J12>0),J12,0)+IF(AND(OR(N12="",LEN(TRIM(N12))=0),ISNUMBER(M12),M12>0),M12,0)+IF(AND(OR(Q12="",LEN(TRIM(Q12))=0),ISNUMBER(P12),P12>0),P12,0)+IF(AND(OR(T12="",LEN(TRIM(T12))=0),ISNUMBER(S12),S12>0),S12,0))>0,IF(AND(OR(H12="",LEN(TRIM(H12))=0),ISNUMBER(G12),G12>0),G12,0)+IF(AND(OR(K12="",LEN(TRIM(K12))=0),ISNUMBER(J12),J12>0),J12,0)+IF(AND(OR(N12="",LEN(TRIM(N12))=0),ISNUMBER(M12),M12>0),M12,0)+IF(AND(OR(Q12="",LEN(TRIM(Q12))=0),ISNUMBER(P12),P12>0),P12,0)+IF(AND(OR(T12="",LEN(TRIM(T12))=0),ISNUMBER(S12),S12>0),S12,0),IF(OR(TRIM(Y12)="UPCOMING",TRIM(Y12)="PENDING"),MAX(0,F12-V12),0))) -> 0
A13: =IF(B13="","",ROW()-4) -> 9 | B13: David Omaghomi | C13: CRM | D13: LCCH SEC 1&2 | E13: Payment for Community Relation Manager retainer fee for 5 months (from June 2025 to October 2025) | F13: 10000000 | S13: 10000000 | T13: 45966 | V13: =IF(TRIM(Y13)="PAID",SUM(G13,J13,M13,P13,S13),IF(AND(H13<>"",LEN(TRIM(H13))>0),G13,0)+IF(AND(K13<>"",LEN(TRIM(K13))>0),J13,0)+IF(AND(N13<>"",LEN(TRIM(N13))>0),M13,0)+IF(AND(Q13<>"",LEN(TRIM(Q13))>0),P13,0)+IF(AND(T13<>"",LEN(TRIM(T13))>0),S13,0)) -> 10000000 | W13: =IF(OR(F13="",F13=0),"",MAX(0,F13-V13-AC13)) -> 0 | X13: =IF(OR(F13=0,F13=""),"-",V13/F13) -> 1 | Y13: PAID | AC13: =IF(TRIM(Y13)="PAID",0,IF((IF(AND(OR(H13="",LEN(TRIM(H13))=0),ISNUMBER(G13),G13>0),G13,0)+IF(AND(OR(K13="",LEN(TRIM(K13))=0),ISNUMBER(J13),J13>0),J13,0)+IF(AND(OR(N13="",LEN(TRIM(N13))=0),ISNUMBER(M13),M13>0),M13,0)+IF(AND(OR(Q13="",LEN(TRIM(Q13))=0),ISNUMBER(P13),P13>0),P13,0)+IF(AND(OR(T13="",LEN(TRIM(T13))=0),ISNUMBER(S13),S13>0),S13,0))>0,IF(AND(OR(H13="",LEN(TRIM(H13))=0),ISNUMBER(G13),G13>0),G13,0)+IF(AND(OR(K13="",LEN(TRIM(K13))=0),ISNUMBER(J13),J13>0),J13,0)+IF(AND(OR(N13="",LEN(TRIM(N13))=0),ISNUMBER(M13),M13>0),M13,0)+IF(AND(OR(Q13="",LEN(TRIM(Q13))=0),ISNUMBER(P13),P13>0),P13,0)+IF(AND(OR(T13="",LEN(TRIM(T13))=0),ISNUMBER(S13),S13>0),S13,0),IF(OR(TRIM(Y13)="UPCOMING",TRIM(Y13)="PENDING"),MAX(0,F13-V13),0))) -> 0
A14: =IF(B14="","",ROW()-4) -> 10 | B14: G&B PRINTING PRESS AND BUSINESS CENTER | C14: CRM | D14: LCCH SEC 1&2 | E14: Office supplies | F14: 300000 | T14: 46080 | V14: =IF(TRIM(Y14)="PAID",SUM(G14,J14,M14,P14,S14),IF(AND(H14<>"",LEN(TRIM(H14))>0),G14,0)+IF(AND(K14<>"",LEN(TRIM(K14))>0),J14,0)+IF(AND(N14<>"",LEN(TRIM(N14))>0),M14,0)+IF(AND(Q14<>"",LEN(TRIM(Q14))>0),P14,0)+IF(AND(T14<>"",LEN(TRIM(T14))>0),S14,0)) -> 0 | W14: =IF(OR(F14="",F14=0),"",MAX(0,F14-V14-AC14)) -> 0 | X14: =IF(OR(F14=0,F14=""),"-",V14/F14) -> 0 | Y14: PENDING | AC14: =IF(TRIM(Y14)="PAID",0,IF((IF(AND(OR(H14="",LEN(TRIM(H14))=0),ISNUMBER(G14),G14>0),G14,0)+IF(AND(OR(K14="",LEN(TRIM(K14))=0),ISNUMBER(J14),J14>0),J14,0)+IF(AND(OR(N14="",LEN(TRIM(N14))=0),ISNUMBER(M14),M14>0),M14,0)+IF(AND(OR(Q14="",LEN(TRIM(Q14))=0),ISNUMBER(P14),P14>0),P14,0)+IF(AND(OR(T14="",LEN(TRIM(T14))=0),ISNUMBER(S14),S14>0),S14,0))>0,IF(AND(OR(H14="",LEN(TRIM(H14))=0),ISNUMBER(G14),G14>0),G14,0)+IF(AND(OR(K14="",LEN(TRIM(K14))=0),ISNUMBER(J14),J14>0),J14,0)+IF(AND(OR(N14="",LEN(TRIM(N14))=0),ISNUMBER(M14),M14>0),M14,0)+IF(AND(OR(Q14="",LEN(TRIM(Q14))=0),ISNUMBER(P14),P14>0),P14,0)+IF(AND(OR(T14="",LEN(TRIM(T14))=0),ISNUMBER(S14),S14>0),S14,0),IF(OR(TRIM(Y14)="UPCOMING",TRIM(Y14)="PENDING"),MAX(0,F14-V14),0))) -> 300000
A15: =IF(B15="","",ROW()-4) -> 11 | B15: G&B PRINTING PRESS AND BUSINESS CENTER | C15: CRM | D15: LCCH SEC 1&2 | E15: Office supplies | F15: 468000 | T15: 46065 | V15: =IF(TRIM(Y15)="PAID",SUM(G15,J15,M15,P15,S15),IF(AND(H15<>"",LEN(TRIM(H15))>0),G15,0)+IF(AND(K15<>"",LEN(TRIM(K15))>0),J15,0)+IF(AND(N15<>"",LEN(TRIM(N15))>0),M15,0)+IF(AND(Q15<>"",LEN(TRIM(Q15))>0),P15,0)+IF(AND(T15<>"",LEN(TRIM(T15))>0),S15,0)) -> 0 | W15: =IF(OR(F15="",F15=0),"",MAX(0,F15-V15-AC15)) -> 0 | X15: =IF(OR(F15=0,F15=""),"-",V15/F15) -> 0 | Y15: PENDING | AC15: =IF(TRIM(Y15)="PAID",0,IF((IF(AND(OR(H15="",LEN(TRIM(H15))=0),ISNUMBER(G15),G15>0),G15,0)+IF(AND(OR(K15="",LEN(TRIM(K15))=0),ISNUMBER(J15),J15>0),J15,0)+IF(AND(OR(N15="",LEN(TRIM(N15))=0),ISNUMBER(M15),M15>0),M15,0)+IF(AND(OR(Q15="",LEN(TRIM(Q15))=0),ISNUMBER(P15),P15>0),P15,0)+IF(AND(OR(T15="",LEN(TRIM(T15))=0),ISNUMBER(S15),S15>0),S15,0))>0,IF(AND(OR(H15="",LEN(TRIM(H15))=0),ISNUMBER(G15),G15>0),G15,0)+IF(AND(OR(K15="",LEN(TRIM(K15))=0),ISNUMBER(J15),J15>0),J15,0)+IF(AND(OR(N15="",LEN(TRIM(N15))=0),ISNUMBER(M15),M15>0),M15,0)+IF(AND(OR(Q15="",LEN(TRIM(Q15))=0),ISNUMBER(P15),P15>0),P15,0)+IF(AND(OR(T15="",LEN(TRIM(T15))=0),ISNUMBER(S15),S15>0),S15,0),IF(OR(TRIM(Y15)="UPCOMING",TRIM(Y15)="PENDING"),MAX(0,F15-V15),0))) -> 468000
A16: =IF(B16="","",ROW()-4) -> 12 | B16: G&B PRINTING PRESS AND BUSINESS CENTER | C16: CRM | D16: LCCH SEC 1&2 | E16: Office supplies | F16: 446500 | T16: 46021 | V16: =IF(TRIM(Y16)="PAID",SUM(G16,J16,M16,P16,S16),IF(AND(H16<>"",LEN(TRIM(H16))>0),G16,0)+IF(AND(K16<>"",LEN(TRIM(K16))>0),J16,0)+IF(AND(N16<>"",LEN(TRIM(N16))>0),M16,0)+IF(AND(Q16<>"",LEN(TRIM(Q16))>0),P16,0)+IF(AND(T16<>"",LEN(TRIM(T16))>0),S16,0)) -> 0 | W16: =IF(OR(F16="",F16=0),"",MAX(0,F16-V16-AC16)) -> 0 | X16: =IF(OR(F16=0,F16=""),"-",V16/F16) -> 0 | Y16: PENDING | AC16: =IF(TRIM(Y16)="PAID",0,IF((IF(AND(OR(H16="",LEN(TRIM(H16))=0),ISNUMBER(G16),G16>0),G16,0)+IF(AND(OR(K16="",LEN(TRIM(K16))=0),ISNUMBER(J16),J16>0),J16,0)+IF(AND(OR(N16="",LEN(TRIM(N16))=0),ISNUMBER(M16),M16>0),M16,0)+IF(AND(OR(Q16="",LEN(TRIM(Q16))=0),ISNUMBER(P16),P16>0),P16,0)+IF(AND(OR(T16="",LEN(TRIM(T16))=0),ISNUMBER(S16),S16>0),S16,0))>0,IF(AND(OR(H16="",LEN(TRIM(H16))=0),ISNUMBER(G16),G16>0),G16,0)+IF(AND(OR(K16="",LEN(TRIM(K16))=0),ISNUMBER(J16),J16>0),J16,0)+IF(AND(OR(N16="",LEN(TRIM(N16))=0),ISNUMBER(M16),M16>0),M16,0)+IF(AND(OR(Q16="",LEN(TRIM(Q16))=0),ISNUMBER(P16),P16>0),P16,0)+IF(AND(OR(T16="",LEN(TRIM(T16))=0),ISNUMBER(S16),S16>0),S16,0),IF(OR(TRIM(Y16)="UPCOMING",TRIM(Y16)="PENDING"),MAX(0,F16-V16),0))) -> 446500
A17: =IF(B17="","",ROW()-4) -> 13 | B17: Beachtv Media Limited | C17: CSR | D17: LCCH SEC 1&2 | E17: Photography - Videography - Drone Shoot | F17: 250000 | T17: 46032 | V17: =IF(TRIM(Y17)="PAID",SUM(G17,J17,M17,P17,S17),IF(AND(H17<>"",LEN(TRIM(H17))>0),G17,0)+IF(AND(K17<>"",LEN(TRIM(K17))>0),J17,0)+IF(AND(N17<>"",LEN(TRIM(N17))>0),M17,0)+IF(AND(Q17<>"",LEN(TRIM(Q17))>0),P17,0)+IF(AND(T17<>"",LEN(TRIM(T17))>0),S17,0)) -> 0 | W17: =IF(OR(F17="",F17=0),"",MAX(0,F17-V17-AC17)) -> 0 | X17: =IF(OR(F17=0,F17=""),"-",V17/F17) -> 0 | Y17: PENDING | AC17: =IF(TRIM(Y17)="PAID",0,IF((IF(AND(OR(H17="",LEN(TRIM(H17))=0),ISNUMBER(G17),G17>0),G17,0)+IF(AND(OR(K17="",LEN(TRIM(K17))=0),ISNUMBER(J17),J17>0),J17,0)+IF(AND(OR(N17="",LEN(TRIM(N17))=0),ISNUMBER(M17),M17>0),M17,0)+IF(AND(OR(Q17="",LEN(TRIM(Q17))=0),ISNUMBER(P17),P17>0),P17,0)+IF(AND(OR(T17="",LEN(TRIM(T17))=0),ISNUMBER(S17),S17>0),S17,0))>0,IF(AND(OR(H17="",LEN(TRIM(H17))=0),ISNUMBER(G17),G17>0),G17,0)+IF(AND(OR(K17="",LEN(TRIM(K17))=0),ISNUMBER(J17),J17>0),J17,0)+IF(AND(OR(N17="",LEN(TRIM(N17))=0),ISNUMBER(M17),M17>0),M17,0)+IF(AND(OR(Q17="",LEN(TRIM(Q17))=0),ISNUMBER(P17),P17>0),P17,0)+IF(AND(OR(T17="",LEN(TRIM(T17))=0),ISNUMBER(S17),S17>0),S17,0),IF(OR(TRIM(Y17)="UPCOMING",TRIM(Y17)="PENDING"),MAX(0,F17-V17),0))) -> 250000
A18: =IF(B18="","",ROW()-4) -> 14 | B18: G&B PRINTING PRESS AND BUSINESS CENTER | C18: CRM | D18: LCCH SEC 1&2 | E18: Office supplies | F18: 300000 | T18: 46000 | V18: =IF(TRIM(Y18)="PAID",SUM(G18,J18,M18,P18,S18),IF(AND(H18<>"",LEN(TRIM(H18))>0),G18,0)+IF(AND(K18<>"",LEN(TRIM(K18))>0),J18,0)+IF(AND(N18<>"",LEN(TRIM(N18))>0),M18,0)+IF(AND(Q18<>"",LEN(TRIM(Q18))>0),P18,0)+IF(AND(T18<>"",LEN(TRIM(T18))>0),S18,0)) -> 0 | W18: =IF(OR(F18="",F18=0),"",MAX(0,F18-V18-AC18)) -> 0 | X18: =IF(OR(F18=0,F18=""),"-",V18/F18) -> 0 | Y18: PENDING | AC18: =IF(TRIM(Y18)="PAID",0,IF((IF(AND(OR(H18="",LEN(TRIM(H18))=0),ISNUMBER(G18),G18>0),G18,0)+IF(AND(OR(K18="",LEN(TRIM(K18))=0),ISNUMBER(J18),J18>0),J18,0)+IF(AND(OR(N18="",LEN(TRIM(N18))=0),ISNUMBER(M18),M18>0),M18,0)+IF(AND(OR(Q18="",LEN(TRIM(Q18))=0),ISNUMBER(P18),P18>0),P18,0)+IF(AND(OR(T18="",LEN(TRIM(T18))=0),ISNUMBER(S18),S18>0),S18,0))>0,IF(AND(OR(H18="",LEN(TRIM(H18))=0),ISNUMBER(G18),G18>0),G18,0)+IF(AND(OR(K18="",LEN(TRIM(K18))=0),ISNUMBER(J18),J18>0),J18,0)+IF(AND(OR(N18="",LEN(TRIM(N18))=0),ISNUMBER(M18),M18>0),M18,0)+IF(AND(OR(Q18="",LEN(TRIM(Q18))=0),ISNUMBER(P18),P18>0),P18,0)+IF(AND(OR(T18="",LEN(TRIM(T18))=0),ISNUMBER(S18),S18>0),S18,0),IF(OR(TRIM(Y18)="UPCOMING",TRIM(Y18)="PENDING"),MAX(0,F18-V18),0))) -> 300000
A19: =IF(B19="","",ROW()-4) -> 15 | B19: Lifeline Option Enterprises | C19: CSR | D19: LCCH SEC 1&2 | E19: Adhoc staffs | F19: 40000 | S19: 40000 | T19: 45992 | V19: =IF(TRIM(Y19)="PAID",SUM(G19,J19,M19,P19,S19),IF(AND(H19<>"",LEN(TRIM(H19))>0),G19,0)+IF(AND(K19<>"",LEN(TRIM(K19))>0),J19,0)+IF(AND(N19<>"",LEN(TRIM(N19))>0),M19,0)+IF(AND(Q19<>"",LEN(TRIM(Q19))>0),P19,0)+IF(AND(T19<>"",LEN(TRIM(T19))>0),S19,0)) -> 40000 | W19: =IF(OR(F19="",F19=0),"",MAX(0,F19-V19-AC19)) -> 0 | X19: =IF(OR(F19=0,F19=""),"-",V19/F19) -> 1 | Y19: PAID | AC19: =IF(TRIM(Y19)="PAID",0,IF((IF(AND(OR(H19="",LEN(TRIM(H19))=0),ISNUMBER(G19),G19>0),G19,0)+IF(AND(OR(K19="",LEN(TRIM(K19))=0),ISNUMBER(J19),J19>0),J19,0)+IF(AND(OR(N19="",LEN(TRIM(N19))=0),ISNUMBER(M19),M19>0),M19,0)+IF(AND(OR(Q19="",LEN(TRIM(Q19))=0),ISNUMBER(P19),P19>0),P19,0)+IF(AND(OR(T19="",LEN(TRIM(T19))=0),ISNUMBER(S19),S19>0),S19,0))>0,IF(AND(OR(H19="",LEN(TRIM(H19))=0),ISNUMBER(G19),G19>0),G19,0)+IF(AND(OR(K19="",LEN(TRIM(K19))=0),ISNUMBER(J19),J19>0),J19,0)+IF(AND(OR(N19="",LEN(TRIM(N19))=0),ISNUMBER(M19),M19>0),M19,0)+IF(AND(OR(Q19="",LEN(TRIM(Q19))=0),ISNUMBER(P19),P19>0),P19,0)+IF(AND(OR(T19="",LEN(TRIM(T19))=0),ISNUMBER(S19),S19>0),S19,0),IF(OR(TRIM(Y19)="UPCOMING",TRIM(Y19)="PENDING"),MAX(0,F19-V19),0))) -> 0
A20: =IF(B20="","",ROW()-4) -> 16 | B20: Lifeline Option Enterprises | C20: CRM | D20: LCCH SEC 1&2 | E20: t | F20: 750000 | S20: 750000 | T20: 45966 | V20: =IF(TRIM(Y20)="PAID",SUM(G20,J20,M20,P20,S20),IF(AND(H20<>"",LEN(TRIM(H20))>0),G20,0)+IF(AND(K20<>"",LEN(TRIM(K20))>0),J20,0)+IF(AND(N20<>"",LEN(TRIM(N20))>0),M20,0)+IF(AND(Q20<>"",LEN(TRIM(Q20))>0),P20,0)+IF(AND(T20<>"",LEN(TRIM(T20))>0),S20,0)) -> 750000 | W20: =IF(OR(F20="",F20=0),"",MAX(0,F20-V20-AC20)) -> 0 | X20: =IF(OR(F20=0,F20=""),"-",V20/F20) -> 1 | Y20: PAID | AC20: =IF(TRIM(Y20)="PAID",0,IF((IF(AND(OR(H20="",LEN(TRIM(H20))=0),ISNUMBER(G20),G20>0),G20,0)+IF(AND(OR(K20="",LEN(TRIM(K20))=0),ISNUMBER(J20),J20>0),J20,0)+IF(AND(OR(N20="",LEN(TRIM(N20))=0),ISNUMBER(M20),M20>0),M20,0)+IF(AND(OR(Q20="",LEN(TRIM(Q20))=0),ISNUMBER(P20),P20>0),P20,0)+IF(AND(OR(T20="",LEN(TRIM(T20))=0),ISNUMBER(S20),S20>0),S20,0))>0,IF(AND(OR(H20="",LEN(TRIM(H20))=0),ISNUMBER(G20),G20>0),G20,0)+IF(AND(OR(K20="",LEN(TRIM(K20))=0),ISNUMBER(J20),J20>0),J20,0)+IF(AND(OR(N20="",LEN(TRIM(N20))=0),ISNUMBER(M20),M20>0),M20,0)+IF(AND(OR(Q20="",LEN(TRIM(Q20))=0),ISNUMBER(P20),P20>0),P20,0)+IF(AND(OR(T20="",LEN(TRIM(T20))=0),ISNUMBER(S20),S20>0),S20,0),IF(OR(TRIM(Y20)="UPCOMING",TRIM(Y20)="PENDING"),MAX(0,F20-V20),0))) -> 0
A21: =IF(B21="","",ROW()-4) -> 17 | B21: Lifeline Option Enterprises | C21: CRM | D21: LCCH SEC 1&2 | E21: Speaker hire - campaign | F21: 50000 | T21: 46000 | V21: =IF(TRIM(Y21)="PAID",SUM(G21,J21,M21,P21,S21),IF(AND(H21<>"",LEN(TRIM(H21))>0),G21,0)+IF(AND(K21<>"",LEN(TRIM(K21))>0),J21,0)+IF(AND(N21<>"",LEN(TRIM(N21))>0),M21,0)+IF(AND(Q21<>"",LEN(TRIM(Q21))>0),P21,0)+IF(AND(T21<>"",LEN(TRIM(T21))>0),S21,0)) -> 0 | W21: =IF(OR(F21="",F21=0),"",MAX(0,F21-V21-AC21)) -> 0 | X21: =IF(OR(F21=0,F21=""),"-",V21/F21) -> 0 | Y21: PENDING | AC21: =IF(TRIM(Y21)="PAID",0,IF((IF(AND(OR(H21="",LEN(TRIM(H21))=0),ISNUMBER(G21),G21>0),G21,0)+IF(AND(OR(K21="",LEN(TRIM(K21))=0),ISNUMBER(J21),J21>0),J21,0)+IF(AND(OR(N21="",LEN(TRIM(N21))=0),ISNUMBER(M21),M21>0),M21,0)+IF(AND(OR(Q21="",LEN(TRIM(Q21))=0),ISNUMBER(P21),P21>0),P21,0)+IF(AND(OR(T21="",LEN(TRIM(T21))=0),ISNUMBER(S21),S21>0),S21,0))>0,IF(AND(OR(H21="",LEN(TRIM(H21))=0),ISNUMBER(G21),G21>0),G21,0)+IF(AND(OR(K21="",LEN(TRIM(K21))=0),ISNUMBER(J21),J21>0),J21,0)+IF(AND(OR(N21="",LEN(TRIM(N21))=0),ISNUMBER(M21),M21>0),M21,0)+IF(AND(OR(Q21="",LEN(TRIM(Q21))=0),ISNUMBER(P21),P21>0),P21,0)+IF(AND(OR(T21="",LEN(TRIM(T21))=0),ISNUMBER(S21),S21>0),S21,0),IF(OR(TRIM(Y21)="UPCOMING",TRIM(Y21)="PENDING"),MAX(0,F21-V21),0))) -> 50000
A22: =IF(B22="","",ROW()-4) -> 18 | B22: Lifeline Option Enterprises | C22: CSR | D22: LCCH SEC 1&2 | E22: Adhoc staffs: Jan 10 to Feb 7. 2026 | F22: 120000 | V22: =IF(TRIM(Y22)="PAID",SUM(G22,J22,M22,P22,S22),IF(AND(H22<>"",LEN(TRIM(H22))>0),G22,0)+IF(AND(K22<>"",LEN(TRIM(K22))>0),J22,0)+IF(AND(N22<>"",LEN(TRIM(N22))>0),M22,0)+IF(AND(Q22<>"",LEN(TRIM(Q22))>0),P22,0)+IF(AND(T22<>"",LEN(TRIM(T22))>0),S22,0)) -> 0 | W22: =IF(OR(F22="",F22=0),"",MAX(0,F22-V22-AC22)) -> 0 | X22: =IF(OR(F22=0,F22=""),"-",V22/F22) -> 0 | Y22: PENDING | AC22: =IF(TRIM(Y22)="PAID",0,IF((IF(AND(OR(H22="",LEN(TRIM(H22))=0),ISNUMBER(G22),G22>0),G22,0)+IF(AND(OR(K22="",LEN(TRIM(K22))=0),ISNUMBER(J22),J22>0),J22,0)+IF(AND(OR(N22="",LEN(TRIM(N22))=0),ISNUMBER(M22),M22>0),M22,0)+IF(AND(OR(Q22="",LEN(TRIM(Q22))=0),ISNUMBER(P22),P22>0),P22,0)+IF(AND(OR(T22="",LEN(TRIM(T22))=0),ISNUMBER(S22),S22>0),S22,0))>0,IF(AND(OR(H22="",LEN(TRIM(H22))=0),ISNUMBER(G22),G22>0),G22,0)+IF(AND(OR(K22="",LEN(TRIM(K22))=0),ISNUMBER(J22),J22>0),J22,0)+IF(AND(OR(N22="",LEN(TRIM(N22))=0),ISNUMBER(M22),M22>0),M22,0)+IF(AND(OR(Q22="",LEN(TRIM(Q22))=0),ISNUMBER(P22),P22>0),P22,0)+IF(AND(OR(T22="",LEN(TRIM(T22))=0),ISNUMBER(S22),S22>0),S22,0),IF(OR(TRIM(Y22)="UPCOMING",TRIM(Y22)="PENDING"),MAX(0,F22-V22),0))) -> 120000
A23: =IF(B23="","",ROW()-4) -> 19 | B23: CRM Office and SRAP Team | C23: ESAP SEC 1 | D23: LCCH SEC 1 | E23: SRAP / GRC STAKEHOLDERS WORKSHOP MEETING 2026 | F23: 872000 | T23: 46116 | V23: =IF(TRIM(Y23)="PAID",SUM(G23,J23,M23,P23,S23),IF(AND(H23<>"",LEN(TRIM(H23))>0),G23,0)+IF(AND(K23<>"",LEN(TRIM(K23))>0),J23,0)+IF(AND(N23<>"",LEN(TRIM(N23))>0),M23,0)+IF(AND(Q23<>"",LEN(TRIM(Q23))>0),P23,0)+IF(AND(T23<>"",LEN(TRIM(T23))>0),S23,0)) -> 0 | W23: =IF(OR(F23="",F23=0),"",MAX(0,F23-V23-AC23)) -> 0 | X23: =IF(OR(F23=0,F23=""),"-",V23/F23) -> 0 | Y23: UPCOMING | AC23: =IF(TRIM(Y23)="PAID",0,IF((IF(AND(OR(H23="",LEN(TRIM(H23))=0),ISNUMBER(G23),G23>0),G23,0)+IF(AND(OR(K23="",LEN(TRIM(K23))=0),ISNUMBER(J23),J23>0),J23,0)+IF(AND(OR(N23="",LEN(TRIM(N23))=0),ISNUMBER(M23),M23>0),M23,0)+IF(AND(OR(Q23="",LEN(TRIM(Q23))=0),ISNUMBER(P23),P23>0),P23,0)+IF(AND(OR(T23="",LEN(TRIM(T23))=0),ISNUMBER(S23),S23>0),S23,0))>0,IF(AND(OR(H23="",LEN(TRIM(H23))=0),ISNUMBER(G23),G23>0),G23,0)+IF(AND(OR(K23="",LEN(TRIM(K23))=0),ISNUMBER(J23),J23>0),J23,0)+IF(AND(OR(N23="",LEN(TRIM(N23))=0),ISNUMBER(M23),M23>0),M23,0)+IF(AND(OR(Q23="",LEN(TRIM(Q23))=0),ISNUMBER(P23),P23>0),P23,0)+IF(AND(OR(T23="",LEN(TRIM(T23))=0),ISNUMBER(S23),S23>0),S23,0),IF(OR(TRIM(Y23)="UPCOMING",TRIM(Y23)="PENDING"),MAX(0,F23-V23),0))) -> 872000
A24: =IF(B24="","",ROW()-4) -> 20 | B24: David Omaghomi | C24: CRM | D24: LCCH SEC 1&2 | E24: Fuel (LSR 58 EZ) | F24: 610000 | S24: 610000 | T24: 46331 | V24: =IF(TRIM(Y24)="PAID",SUM(G24,J24,M24,P24,S24),IF(AND(H24<>"",LEN(TRIM(H24))>0),G24,0)+IF(AND(K24<>"",LEN(TRIM(K24))>0),J24,0)+IF(AND(N24<>"",LEN(TRIM(N24))>0),M24,0)+IF(AND(Q24<>"",LEN(TRIM(Q24))>0),P24,0)+IF(AND(T24<>"",LEN(TRIM(T24))>0),S24,0)) -> 610000 | W24: =IF(OR(F24="",F24=0),"",MAX(0,F24-V24-AC24)) -> 0 | X24: =IF(OR(F24=0,F24=""),"-",V24/F24) -> 1 | Y24: PAID | AC24: =IF(TRIM(Y24)="PAID",0,IF((IF(AND(OR(H24="",LEN(TRIM(H24))=0),ISNUMBER(G24),G24>0),G24,0)+IF(AND(OR(K24="",LEN(TRIM(K24))=0),ISNUMBER(J24),J24>0),J24,0)+IF(AND(OR(N24="",LEN(TRIM(N24))=0),ISNUMBER(M24),M24>0),M24,0)+IF(AND(OR(Q24="",LEN(TRIM(Q24))=0),ISNUMBER(P24),P24>0),P24,0)+IF(AND(OR(T24="",LEN(TRIM(T24))=0),ISNUMBER(S24),S24>0),S24,0))>0,IF(AND(OR(H24="",LEN(TRIM(H24))=0),ISNUMBER(G24),G24>0),G24,0)+IF(AND(OR(K24="",LEN(TRIM(K24))=0),ISNUMBER(J24),J24>0),J24,0)+IF(AND(OR(N24="",LEN(TRIM(N24))=0),ISNUMBER(M24),M24>0),M24,0)+IF(AND(OR(Q24="",LEN(TRIM(Q24))=0),ISNUMBER(P24),P24>0),P24,0)+IF(AND(OR(T24="",LEN(TRIM(T24))=0),ISNUMBER(S24),S24>0),S24,0),IF(OR(TRIM(Y24)="UPCOMING",TRIM(Y24)="PENDING"),MAX(0,F24-V24),0))) -> 0
A25: =IF(B25="","",ROW()-4) -> 21 | B25: David Omaghomi | C25: CRM | D25: LCCH SEC 1&2 | E25: April Pay for Community Relations Manager | F25: 2000000 | S25: 2000000 | T25: 45792 | V25: =IF(TRIM(Y25)="PAID",SUM(G25,J25,M25,P25,S25),IF(AND(H25<>"",LEN(TRIM(H25))>0),G25,0)+IF(AND(K25<>"",LEN(TRIM(K25))>0),J25,0)+IF(AND(N25<>"",LEN(TRIM(N25))>0),M25,0)+IF(AND(Q25<>"",LEN(TRIM(Q25))>0),P25,0)+IF(AND(T25<>"",LEN(TRIM(T25))>0),S25,0)) -> 2000000 | W25: =IF(OR(F25="",F25=0),"",MAX(0,F25-V25-AC25)) -> 0 | X25: =IF(OR(F25=0,F25=""),"-",V25/F25) -> 1 | Y25: PAID | AC25: =IF(TRIM(Y25)="PAID",0,IF((IF(AND(OR(H25="",LEN(TRIM(H25))=0),ISNUMBER(G25),G25>0),G25,0)+IF(AND(OR(K25="",LEN(TRIM(K25))=0),ISNUMBER(J25),J25>0),J25,0)+IF(AND(OR(N25="",LEN(TRIM(N25))=0),ISNUMBER(M25),M25>0),M25,0)+IF(AND(OR(Q25="",LEN(TRIM(Q25))=0),ISNUMBER(P25),P25>0),P25,0)+IF(AND(OR(T25="",LEN(TRIM(T25))=0),ISNUMBER(S25),S25>0),S25,0))>0,IF(AND(OR(H25="",LEN(TRIM(H25))=0),ISNUMBER(G25),G25>0),G25,0)+IF(AND(OR(K25="",LEN(TRIM(K25))=0),ISNUMBER(J25),J25>0),J25,0)+IF(AND(OR(N25="",LEN(TRIM(N25))=0),ISNUMBER(M25),M25>0),M25,0)+IF(AND(OR(Q25="",LEN(TRIM(Q25))=0),ISNUMBER(P25),P25>0),P25,0)+IF(AND(OR(T25="",LEN(TRIM(T25))=0),ISNUMBER(S25),S25>0),S25,0),IF(OR(TRIM(Y25)="UPCOMING",TRIM(Y25)="PENDING"),MAX(0,F25-V25),0))) -> 0
A26: =IF(B26="","",ROW()-4) -> 22 | B26: Ndoni Logistic | C26: CRM | D26: LCCH SEC 1&2 | E26: Provision of vehicule Hire (SUV) + Driver & Fueling | F26: 1600000 | S26: 1600000 | V26: =IF(TRIM(Y26)="PAID",SUM(G26,J26,M26,P26,S26),IF(AND(H26<>"",LEN(TRIM(H26))>0),G26,0)+IF(AND(K26<>"",LEN(TRIM(K26))>0),J26,0)+IF(AND(N26<>"",LEN(TRIM(N26))>0),M26,0)+IF(AND(Q26<>"",LEN(TRIM(Q26))>0),P26,0)+IF(AND(T26<>"",LEN(TRIM(T26))>0),S26,0)) -> 1600000 | W26: =IF(OR(F26="",F26=0),"",MAX(0,F26-V26-AC26)) -> 0 | X26: =IF(OR(F26=0,F26=""),"-",V26/F26) -> 1 | Y26: PAID | AC26: =IF(TRIM(Y26)="PAID",0,IF((IF(AND(OR(H26="",LEN(TRIM(H26))=0),ISNUMBER(G26),G26>0),G26,0)+IF(AND(OR(K26="",LEN(TRIM(K26))=0),ISNUMBER(J26),J26>0),J26,0)+IF(AND(OR(N26="",LEN(TRIM(N26))=0),ISNUMBER(M26),M26>0),M26,0)+IF(AND(OR(Q26="",LEN(TRIM(Q26))=0),ISNUMBER(P26),P26>0),P26,0)+IF(AND(OR(T26="",LEN(TRIM(T26))=0),ISNUMBER(S26),S26>0),S26,0))>0,IF(AND(OR(H26="",LEN(TRIM(H26))=0),ISNUMBER(G26),G26>0),G26,0)+IF(AND(OR(K26="",LEN(TRIM(K26))=0),ISNUMBER(J26),J26>0),J26,0)+IF(AND(OR(N26="",LEN(TRIM(N26))=0),ISNUMBER(M26),M26>0),M26,0)+IF(AND(OR(Q26="",LEN(TRIM(Q26))=0),ISNUMBER(P26),P26>0),P26,0)+IF(AND(OR(T26="",LEN(TRIM(T26))=0),ISNUMBER(S26),S26>0),S26,0),IF(OR(TRIM(Y26)="UPCOMING",TRIM(Y26)="PENDING"),MAX(0,F26-V26),0))) -> 0
A27: =IF(B27="","",ROW()-4) -> 23 | B27: David Omaghomi | C27: CRM | D27: LCCH SEC 1&2 | E27: Payment for Community Relation Manager | F27: 2554000 | S27: 2554000 | V27: =IF(TRIM(Y27)="PAID",SUM(G27,J27,M27,P27,S27),IF(AND(H27<>"",LEN(TRIM(H27))>0),G27,0)+IF(AND(K27<>"",LEN(TRIM(K27))>0),J27,0)+IF(AND(N27<>"",LEN(TRIM(N27))>0),M27,0)+IF(AND(Q27<>"",LEN(TRIM(Q27))>0),P27,0)+IF(AND(T27<>"",LEN(TRIM(T27))>0),S27,0)) -> 2554000 | W27: =IF(OR(F27="",F27=0),"",MAX(0,F27-V27-AC27)) -> 0 | X27: =IF(OR(F27=0,F27=""),"-",V27/F27) -> 1 | Y27: PAID | AC27: =IF(TRIM(Y27)="PAID",0,IF((IF(AND(OR(H27="",LEN(TRIM(H27))=0),ISNUMBER(G27),G27>0),G27,0)+IF(AND(OR(K27="",LEN(TRIM(K27))=0),ISNUMBER(J27),J27>0),J27,0)+IF(AND(OR(N27="",LEN(TRIM(N27))=0),ISNUMBER(M27),M27>0),M27,0)+IF(AND(OR(Q27="",LEN(TRIM(Q27))=0),ISNUMBER(P27),P27>0),P27,0)+IF(AND(OR(T27="",LEN(TRIM(T27))=0),ISNUMBER(S27),S27>0),S27,0))>0,IF(AND(OR(H27="",LEN(TRIM(H27))=0),ISNUMBER(G27),G27>0),G27,0)+IF(AND(OR(K27="",LEN(TRIM(K27))=0),ISNUMBER(J27),J27>0),J27,0)+IF(AND(OR(N27="",LEN(TRIM(N27))=0),ISNUMBER(M27),M27>0),M27,0)+IF(AND(OR(Q27="",LEN(TRIM(Q27))=0),ISNUMBER(P27),P27>0),P27,0)+IF(AND(OR(T27="",LEN(TRIM(T27))=0),ISNUMBER(S27),S27>0),S27,0),IF(OR(TRIM(Y27)="UPCOMING",TRIM(Y27)="PENDING"),MAX(0,F27-V27),0))) -> 0
A28: =IF(B28="","",ROW()-4) -> 24 | B28: Ndoni Logistic | C28: CRM | D28: LCCH SEC 1&2 | E28: Vehicule Hire- CRM Office June-July | F28: 1500000 | S28: 1500000 | T28: 45966 | V28: =IF(TRIM(Y28)="PAID",SUM(G28,J28,M28,P28,S28),IF(AND(H28<>"",LEN(TRIM(H28))>0),G28,0)+IF(AND(K28<>"",LEN(TRIM(K28))>0),J28,0)+IF(AND(N28<>"",LEN(TRIM(N28))>0),M28,0)+IF(AND(Q28<>"",LEN(TRIM(Q28))>0),P28,0)+IF(AND(T28<>"",LEN(TRIM(T28))>0),S28,0)) -> 1500000 | W28: =IF(OR(F28="",F28=0),"",MAX(0,F28-V28-AC28)) -> 0 | X28: =IF(OR(F28=0,F28=""),"-",V28/F28) -> 1 | Y28: PAID | AC28: =IF(TRIM(Y28)="PAID",0,IF((IF(AND(OR(H28="",LEN(TRIM(H28))=0),ISNUMBER(G28),G28>0),G28,0)+IF(AND(OR(K28="",LEN(TRIM(K28))=0),ISNUMBER(J28),J28>0),J28,0)+IF(AND(OR(N28="",LEN(TRIM(N28))=0),ISNUMBER(M28),M28>0),M28,0)+IF(AND(OR(Q28="",LEN(TRIM(Q28))=0),ISNUMBER(P28),P28>0),P28,0)+IF(AND(OR(T28="",LEN(TRIM(T28))=0),ISNUMBER(S28),S28>0),S28,0))>0,IF(AND(OR(H28="",LEN(TRIM(H28))=0),ISNUMBER(G28),G28>0),G28,0)+IF(AND(OR(K28="",LEN(TRIM(K28))=0),ISNUMBER(J28),J28>0),J28,0)+IF(AND(OR(N28="",LEN(TRIM(N28))=0),ISNUMBER(M28),M28>0),M28,0)+IF(AND(OR(Q28="",LEN(TRIM(Q28))=0),ISNUMBER(P28),P28>0),P28,0)+IF(AND(OR(T28="",LEN(TRIM(T28))=0),ISNUMBER(S28),S28>0),S28,0),IF(OR(TRIM(Y28)="UPCOMING",TRIM(Y28)="PENDING"),MAX(0,F28-V28),0))) -> 0
A29: =IF(B29="","",ROW()-4) -> 25 | B29: David Omaghomi | C29: CRM | D29: LCCH SEC 1 | E29: Payment for Community Relation Manager | F29: 3050000 | S29: 3050000 | T29: 45708 | V29: =IF(TRIM(Y29)="PAID",SUM(G29,J29,M29,P29,S29),IF(AND(H29<>"",LEN(TRIM(H29))>0),G29,0)+IF(AND(K29<>"",LEN(TRIM(K29))>0),J29,0)+IF(AND(N29<>"",LEN(TRIM(N29))>0),M29,0)+IF(AND(Q29<>"",LEN(TRIM(Q29))>0),P29,0)+IF(AND(T29<>"",LEN(TRIM(T29))>0),S29,0)) -> 3050000 | W29: =IF(OR(F29="",F29=0),"",MAX(0,F29-V29-AC29)) -> 0 | X29: =IF(OR(F29=0,F29=""),"-",V29/F29) -> 1 | Y29: PAID | AC29: =IF(TRIM(Y29)="PAID",0,IF((IF(AND(OR(H29="",LEN(TRIM(H29))=0),ISNUMBER(G29),G29>0),G29,0)+IF(AND(OR(K29="",LEN(TRIM(K29))=0),ISNUMBER(J29),J29>0),J29,0)+IF(AND(OR(N29="",LEN(TRIM(N29))=0),ISNUMBER(M29),M29>0),M29,0)+IF(AND(OR(Q29="",LEN(TRIM(Q29))=0),ISNUMBER(P29),P29>0),P29,0)+IF(AND(OR(T29="",LEN(TRIM(T29))=0),ISNUMBER(S29),S29>0),S29,0))>0,IF(AND(OR(H29="",LEN(TRIM(H29))=0),ISNUMBER(G29),G29>0),G29,0)+IF(AND(OR(K29="",LEN(TRIM(K29))=0),ISNUMBER(J29),J29>0),J29,0)+IF(AND(OR(N29="",LEN(TRIM(N29))=0),ISNUMBER(M29),M29>0),M29,0)+IF(AND(OR(Q29="",LEN(TRIM(Q29))=0),ISNUMBER(P29),P29>0),P29,0)+IF(AND(OR(T29="",LEN(TRIM(T29))=0),ISNUMBER(S29),S29>0),S29,0),IF(OR(TRIM(Y29)="UPCOMING",TRIM(Y29)="PENDING"),MAX(0,F29-V29),0))) -> 0
A30: =IF(B30="","",ROW()-4) -> 26 | B30: Lifeline Option Enterprises | C30: CSR | D30: LCCH SEC 1&2 | E30: Adhoc staffs 14 feb. 2026 | F30: 40000 | V30: =IF(TRIM(Y30)="PAID",SUM(G30,J30,M30,P30,S30),IF(AND(H30<>"",LEN(TRIM(H30))>0),G30,0)+IF(AND(K30<>"",LEN(TRIM(K30))>0),J30,0)+IF(AND(N30<>"",LEN(TRIM(N30))>0),M30,0)+IF(AND(Q30<>"",LEN(TRIM(Q30))>0),P30,0)+IF(AND(T30<>"",LEN(TRIM(T30))>0),S30,0)) -> 0 | W30: =IF(OR(F30="",F30=0),"",MAX(0,F30-V30-AC30)) -> 0 | X30: =IF(OR(F30=0,F30=""),"-",V30/F30) -> 0 | Y30: PENDING | AC30: =IF(TRIM(Y30)="PAID",0,IF((IF(AND(OR(H30="",LEN(TRIM(H30))=0),ISNUMBER(G30),G30>0),G30,0)+IF(AND(OR(K30="",LEN(TRIM(K30))=0),ISNUMBER(J30),J30>0),J30,0)+IF(AND(OR(N30="",LEN(TRIM(N30))=0),ISNUMBER(M30),M30>0),M30,0)+IF(AND(OR(Q30="",LEN(TRIM(Q30))=0),ISNUMBER(P30),P30>0),P30,0)+IF(AND(OR(T30="",LEN(TRIM(T30))=0),ISNUMBER(S30),S30>0),S30,0))>0,IF(AND(OR(H30="",LEN(TRIM(H30))=0),ISNUMBER(G30),G30>0),G30,0)+IF(AND(OR(K30="",LEN(TRIM(K30))=0),ISNUMBER(J30),J30>0),J30,0)+IF(AND(OR(N30="",LEN(TRIM(N30))=0),ISNUMBER(M30),M30>0),M30,0)+IF(AND(OR(Q30="",LEN(TRIM(Q30))=0),ISNUMBER(P30),P30>0),P30,0)+IF(AND(OR(T30="",LEN(TRIM(T30))=0),ISNUMBER(S30),S30>0),S30,0),IF(OR(TRIM(Y30)="UPCOMING",TRIM(Y30)="PENDING"),MAX(0,F30-V30),0))) -> 40000
A31: =IF(B31="","",ROW()-4) -> 27 | B31: David Omaghomi | C31: CRM | D31: LCCH SEC 1&2 | E31: Payment for CRM Office Nov 2025 to March 2026 | F31: 10000000 | V31: =IF(TRIM(Y31)="PAID",SUM(G31,J31,M31,P31,S31),IF(AND(H31<>"",LEN(TRIM(H31))>0),G31,0)+IF(AND(K31<>"",LEN(TRIM(K31))>0),J31,0)+IF(AND(N31<>"",LEN(TRIM(N31))>0),M31,0)+IF(AND(Q31<>"",LEN(TRIM(Q31))>0),P31,0)+IF(AND(T31<>"",LEN(TRIM(T31))>0),S31,0)) -> 0 | W31: =IF(OR(F31="",F31=0),"",MAX(0,F31-V31-AC31)) -> 0 | X31: =IF(OR(F31=0,F31=""),"-",V31/F31) -> 0 | Y31: PENDING | AC31: =IF(TRIM(Y31)="PAID",0,IF((IF(AND(OR(H31="",LEN(TRIM(H31))=0),ISNUMBER(G31),G31>0),G31,0)+IF(AND(OR(K31="",LEN(TRIM(K31))=0),ISNUMBER(J31),J31>0),J31,0)+IF(AND(OR(N31="",LEN(TRIM(N31))=0),ISNUMBER(M31),M31>0),M31,0)+IF(AND(OR(Q31="",LEN(TRIM(Q31))=0),ISNUMBER(P31),P31>0),P31,0)+IF(AND(OR(T31="",LEN(TRIM(T31))=0),ISNUMBER(S31),S31>0),S31,0))>0,IF(AND(OR(H31="",LEN(TRIM(H31))=0),ISNUMBER(G31),G31>0),G31,0)+IF(AND(OR(K31="",LEN(TRIM(K31))=0),ISNUMBER(J31),J31>0),J31,0)+IF(AND(OR(N31="",LEN(TRIM(N31))=0),ISNUMBER(M31),M31>0),M31,0)+IF(AND(OR(Q31="",LEN(TRIM(Q31))=0),ISNUMBER(P31),P31>0),P31,0)+IF(AND(OR(T31="",LEN(TRIM(T31))=0),ISNUMBER(S31),S31>0),S31,0),IF(OR(TRIM(Y31)="UPCOMING",TRIM(Y31)="PENDING"),MAX(0,F31-V31),0))) -> 10000000
A32: =IF(B32="","",ROW()-4) -> 28 | B32: EcoConserv | C32: ESAP SEC 1 | D32: LCCH SEC 1 | E32: HURRI - LCCH 30% | F32: 24612600 | G32: 7383780 | H32: 45903 | J32: 9379015 | L32: HURRI-LCCH 40% (à venir) | V32: =IF(TRIM(Y32)="PAID",SUM(G32,J32,M32,P32,S32),IF(AND(H32<>"",LEN(TRIM(H32))>0),G32,0)+IF(AND(K32<>"",LEN(TRIM(K32))>0),J32,0)+IF(AND(N32<>"",LEN(TRIM(N32))>0),M32,0)+IF(AND(Q32<>"",LEN(TRIM(Q32))>0),P32,0)+IF(AND(T32<>"",LEN(TRIM(T32))>0),S32,0)) -> 7383780 | W32: =IF(OR(F32="",F32=0),"",MAX(0,F32-V32-AC32)) -> 7849805 | X32: =IF(OR(F32=0,F32=""),"-",V32/F32) -> 0.3 | Y32: PARTIAL | AB32: 30% payé (T1) + 40% à venir (T2). Solde 30% restant. | AC32: =IF(TRIM(Y32)="PAID",0,IF((IF(AND(OR(H32="",LEN(TRIM(H32))=0),ISNUMBER(G32),G32>0),G32,0)+IF(AND(OR(K32="",LEN(TRIM(K32))=0),ISNUMBER(J32),J32>0),J32,0)+IF(AND(OR(N32="",LEN(TRIM(N32))=0),ISNUMBER(M32),M32>0),M32,0)+IF(AND(OR(Q32="",LEN(TRIM(Q32))=0),ISNUMBER(P32),P32>0),P32,0)+IF(AND(OR(T32="",LEN(TRIM(T32))=0),ISNUMBER(S32),S32>0),S32,0))>0,IF(AND(OR(H32="",LEN(TRIM(H32))=0),ISNUMBER(G32),G32>0),G32,0)+IF(AND(OR(K32="",LEN(TRIM(K32))=0),ISNUMBER(J32),J32>0),J32,0)+IF(AND(OR(N32="",LEN(TRIM(N32))=0),ISNUMBER(M32),M32>0),M32,0)+IF(AND(OR(Q32="",LEN(TRIM(Q32))=0),ISNUMBER(P32),P32>0),P32,0)+IF(AND(OR(T32="",LEN(TRIM(T32))=0),ISNUMBER(S32),S32>0),S32,0),IF(OR(TRIM(Y32)="UPCOMING",TRIM(Y32)="PENDING"),MAX(0,F32-V32),0))) -> 9379015
A33: =IF(B33="","",ROW()-4) -> 29 | B33: Hitech | C33: ESAP-SRAP | D33: LCCH SEC 1 | E33: SRAP/GRC Activities- April, 4, 2026 | F33: 9228000 | V33: =IF(TRIM(Y33)="PAID",SUM(G33,J33,M33,P33,S33),IF(AND(H33<>"",LEN(TRIM(H33))>0),G33,0)+IF(AND(K33<>"",LEN(TRIM(K33))>0),J33,0)+IF(AND(N33<>"",LEN(TRIM(N33))>0),M33,0)+IF(AND(Q33<>"",LEN(TRIM(Q33))>0),P33,0)+IF(AND(T33<>"",LEN(TRIM(T33))>0),S33,0)) -> 0 | W33: =IF(OR(F33="",F33=0),"",MAX(0,F33-V33-AC33)) -> 0 | X33: =IF(OR(F33=0,F33=""),"-",V33/F33) -> 0 | Y33: UPCOMING | AC33: =IF(TRIM(Y33)="PAID",0,IF((IF(AND(OR(H33="",LEN(TRIM(H33))=0),ISNUMBER(G33),G33>0),G33,0)+IF(AND(OR(K33="",LEN(TRIM(K33))=0),ISNUMBER(J33),J33>0),J33,0)+IF(AND(OR(N33="",LEN(TRIM(N33))=0),ISNUMBER(M33),M33>0),M33,0)+IF(AND(OR(Q33="",LEN(TRIM(Q33))=0),ISNUMBER(P33),P33>0),P33,0)+IF(AND(OR(T33="",LEN(TRIM(T33))=0),ISNUMBER(S33),S33>0),S33,0))>0,IF(AND(OR(H33="",LEN(TRIM(H33))=0),ISNUMBER(G33),G33>0),G33,0)+IF(AND(OR(K33="",LEN(TRIM(K33))=0),ISNUMBER(J33),J33>0),J33,0)+IF(AND(OR(N33="",LEN(TRIM(N33))=0),ISNUMBER(M33),M33>0),M33,0)+IF(AND(OR(Q33="",LEN(TRIM(Q33))=0),ISNUMBER(P33),P33>0),P33,0)+IF(AND(OR(T33="",LEN(TRIM(T33))=0),ISNUMBER(S33),S33>0),S33,0),IF(OR(TRIM(Y33)="UPCOMING",TRIM(Y33)="PENDING"),MAX(0,F33-V33),0))) -> 9228000
